<?xml version="1.0" encoding="utf-8"?>
<robot name="ghost">
  <material name="black">
    <color rgba="0.0 0.0 0.0 1.0"/>
  </material>
  <material name="blue">
    <color rgba="0.0 0.0 0.8 1.0"/>
  </material>
  <material name="grey">
    <color rgba="0.6 0.6 0.6 1"/>
  </material>

  <link name="trunk">
    <visual>
      <origin rpy="0 0 -1.5708" xyz="0 0 0"/>
      <geometry>
        <mesh filename="ghost/body.obj" scale="1 1 1"/>
      </geometry>
      <material name="black"/>
    </visual>
    <!-- <collision>
      <origin rpy="0 0 0" xyz="0 0 0"/>
      <geometry>
        <box size="0.267 0.194 0.114"/>
      </geometry>
    </collision> -->
    <collision>
      <origin rpy="0 0 0" xyz="0 0 0"/>
      <geometry>
        <mesh filename="ghost/body.obj" scale="1 1 1"/>
      </geometry>
    </collision>
    <inertial>
      <origin rpy="0 0 0" xyz="0 0 0"/>
       <mass value="13.715"/>
       <inertia ixx="0.22" ixy="0" ixz="0" iyy="0.431" iyz="0" izz="0.565"/>
    </inertial>
  </link>

  <!-- FR HIP -->
  <link name="FR_hip">
    <!-- <contact>
      <lateral_friction value="1"/>
    </contact> -->
    <inertial>
       <origin rpy="0 0 0" xyz="0.02 0 0"/>
       <mass value="1.095"/>
       <inertia ixx="0.002" ixy="0" ixz="0" iyy=".002" iyz="0" izz=".001"/>
    </inertial>

    <visual>
      <origin rpy="0 0 0" xyz="0 0 0"/>
      <geometry>
        <mesh filename="ghost/hip.obj" scale="1 1 1"/>
      </geometry>
       <material name="blue"/>
    </visual>

    <collision>
      <origin rpy="0 0 0" xyz="0 0 0"/>
      <geometry>
        <mesh filename="ghost/hip.obj" scale="1 1 1"/>
      </geometry>
    </collision>
  </link>

  <joint name="FR_hip_joint" type="continuous">
    <axis xyz="1 0 0"/>
    <parent link="trunk"/>
    <child link="FR_hip"/>
    <origin rpy="1.57079 0 3.14159" xyz="0.22 -0.06 0.0"/>
    <limit effort="100" velocity="100"/>
    <joint_properties damping=".0" friction=".0"/>
  </joint>

  <!-- FR UPPER LEG -->
  <link name="FR_upper">
  <!-- <contact>
      <lateral_friction value="1"/>
  </contact> -->
    <inertial>
     <origin rpy="0 0 0" xyz="0 -0.04 -0.04"/>
       <mass value="1.527"/>
       <inertia ixx="0.015" ixy="0" ixz="0" iyy="0.007" iyz="0" izz="0.01"/>
    </inertial>
    <visual>
      <origin rpy="0 0 0" xyz="0 0 0"/>
      <geometry>
        <mesh filename="ghost/upper_leg_mirror.obj" scale="1 1 1"/>
      </geometry>
      <material name="blue"/>
    </visual>

    <collision>
      <origin rpy="0 0 0" xyz="0 0 0"/>
      <geometry>
        <mesh filename="ghost/upper_leg_mirror.obj" scale="1 1 1"/>
      </geometry>
    </collision>
  </link>

  <joint name="FR_upper_joint" type="continuous">
    <axis xyz="0 1 0"/>
    <parent link="FR_hip"/>
    <child link="FR_upper"/>
    <origin rpy="1.57079 0 1.57079" xyz="-0.0015 0 -0.095"/>
    <limit effort="100" velocity="100"/>
    <joint_properties damping=".0" friction=".0"/>
  </joint>

  <!-- FR LOWER LEG -->
  <link name="FR_lower">
  <!-- <contact>
      <lateral_friction value="1"/>
  </contact> -->
    <inertial>
      <origin rpy="0 0 0" xyz="0 -0.16 -0.02"/>
       <mass value="0.241"/>
       <inertia ixx="0.002" ixy="0" ixz="0" iyy="0.002" iyz="0" izz="0.002"/>
    </inertial>
    <visual>
      <origin rpy="1.57079 1.57079 0" xyz="0 0.0 0"/>
      <geometry>
        <mesh filename="ghost/lower_leg.obj" scale="1 1 1"/>
      </geometry>
       <material name="grey"/>
    </visual>

    <collision>
      <origin rpy="1.57079 1.57079 0" xyz="0 0.0 0"/>
      <geometry>
        <mesh filename="ghost/lower_leg.obj" scale="1 1 1"/>
      </geometry>
    </collision>
  </link>

  <joint name="FR_lower_joint" type="continuous">
    <axis xyz="0 1 0"/>
    <parent link="FR_upper"/>
    <child link="FR_lower"/>
    <origin rpy="0 0 0" xyz="-0.25 -0.005 0.006"/>
    <limit effort="100" velocity="100"/>
    <joint_properties damping=".0" friction=".0"/>
  </joint>

  <!-- FR TOE -->
  <link name="FR_toe">
    <!-- <contact>
      <friction_anchor/>
      <stiffness value="30000.0"/>
      <damping value="1000.0"/>
      <spinning_friction value="0.1"/>
      <lateral_friction value="1.0"/>
    </contact> -->
    <visual>
      <origin rpy="0 0 0" xyz="0 0 0"/>
      <geometry>
        <sphere radius="0.0"/>
      </geometry>
      <material name="black"/>
    </visual>
    <collision>
      <origin rpy="0 0 0" xyz="0 0 0"/>
      <geometry>
        <sphere radius="0.03"/>
      </geometry>
    </collision>
    <inertial>
      <mass value="0.1"/>
      <inertia ixx="0.000025" ixy="0" ixz="0" iyy="0.000025" iyz="0" izz="0.000025"/>
    </inertial>
  </link>

  <joint name="FR_toe_fixed" type="fixed">
    <parent link="FR_lower"/>
    <child link="FR_toe"/>
    <origin xyz="-0.25 0 -0.02"/>
    <dynamics damping="0.0" friction="0.0"/>
  </joint>

  <!-- FL HIP -->
  <link name="FL_hip">
  <!-- <contact>
      <lateral_friction value="1"/>
  </contact> -->
    <inertial>
     <origin rpy="0 0 0" xyz="-.02 0 0"/>
       <mass value="1.095"/>
       <inertia ixx="0.002" ixy="0" ixz="0" iyy="0.002" iyz="0" izz="0.001"/>
    </inertial>
    <visual>
      <origin rpy="0 0 0" xyz="0 0 0"/>
      <geometry>
        <mesh filename="ghost/hip.obj" scale="1 1 1"/>
      </geometry>
       <material name="blue">
      </material>
    </visual>

    <collision>
      <origin rpy="0 0 0" xyz="0 0 0"/>
      <geometry>
        <mesh filename="ghost/hip.obj" scale="1 1 1"/>
      </geometry>
    </collision>
  </link>

  <joint name="FL_hip_joint" type="continuous">
    <axis xyz="1 0 0"/>
    <parent link="trunk"/>
    <child link="FL_hip"/>
    <origin rpy="-1.57079 0 3.14159" xyz="0.22 0.06 0.0"/>
    <limit effort="100" velocity="100"/>
    <joint_properties damping=".0" friction=".0"/>
  </joint>

  <!-- FL UPPER LEG -->
  <link name="FL_upper">
  <!-- <contact>
      <lateral_friction value="1"/>
  </contact> -->
    <inertial>
       <origin rpy="0 0 0" xyz="0 -0.04 -0.04"/>
       <mass value="1.527"/>
       <inertia ixx="0.016" ixy="0" ixz="0" iyy="0.007" iyz="0" izz="0.011"/>
    </inertial>
     <visual>
      <origin rpy="0 0 0" xyz="0 0 0"/>
      <geometry>

        <mesh filename="ghost/upper_leg.obj" scale="1 1 1"/>
      </geometry>
       <material name="blue">
      </material>
    </visual>

     <collision>
      <origin rpy="0 0 0" xyz="0 0 0"/>
      <geometry>
        <mesh filename="ghost/upper_leg.obj" scale="1 1 1"/>
      </geometry>
    </collision>
  </link>


  <joint name="FL_upper_joint" type="continuous">
    <axis xyz="0 0 -1"/>
    <parent link="FL_hip"/>
    <child link="FL_upper"/>
    <origin rpy="0 0 3.14159" xyz="-0.0015 0 -0.101"/>
    <limit effort="100" velocity="100"/>
    <joint_properties damping=".0" friction=".0"/>
  </joint>

  <!-- FL LOWER LEG -->
  <link name="FL_lower">
  <!-- <contact>
      <lateral_friction value="1"/>
  </contact> -->
    <inertial>
      <origin rpy="0 0 0" xyz="0 -0.16 -0.02"/>
       <mass value="0.241"/>
       <inertia ixx="0.002" ixy="0" ixz="0" iyy="0.002" iyz="0" izz="0.002"/>
    </inertial>
   <visual>
      <origin rpy="0 0 0" xyz="0 0 0"/>
      <geometry>
        <mesh filename="ghost/lower_leg.obj" scale="1 1 1"/>
      </geometry>
       <material name="grey">
       </material>
    </visual>

     <collision>
      <origin rpy="0 0 0" xyz="0 0 0"/>
      <geometry>
        <mesh filename="ghost/lower_leg.obj" scale="1 1 1"/>
      </geometry>
    </collision>
  </link>

  <joint name="FL_lower_joint" type="continuous">
    <axis xyz="0 0 -1"/>
    <parent link="FL_upper"/>
    <child link="FL_lower"/>
    <origin rpy="0 0 0" xyz="-0.005 -0.25 0.006"/>
    <limit effort="100" velocity="100"/>
    <joint_properties damping=".0" friction=".0"/>
  </joint>

  <!-- FL TOE -->
  <link name="FL_toe">
    <!-- <contact>
      <friction_anchor/>
      <stiffness value="30000.0"/>
      <damping value="1000.0"/>
      <spinning_friction value="0.1"/>
      <lateral_friction value="1.0"/>
    </contact> -->
    <visual>
      <origin rpy="0 0 0" xyz="0 0 0"/>
      <geometry>
        <sphere radius="0.0"/>
      </geometry>
      <material name="black"/>
    </visual>
    <collision>
      <origin rpy="0 0 0" xyz="0 0 0"/>
      <geometry>
        <sphere radius="0.03"/>
      </geometry>
    </collision>
    <inertial>
      <mass value="0.1"/>
      <inertia ixx="0.000025" ixy="0" ixz="0" iyy="0.000025" iyz="0" izz="0.000025"/>
    </inertial>
  </link>

  <joint name="FL_toe_fixed" type="fixed">
    <parent link="FL_lower"/>
    <child link="FL_toe"/>
    <origin xyz="0.02 -0.25 0"/>
    <dynamics damping="0.0" friction="0.0"/>
  </joint>

  <!-- RR HIP -->
  <link name="RR_hip">
  <!-- <contact>
      <lateral_friction value="1"/>
  </contact> -->
    <inertial>
      <origin rpy="0 0 0" xyz="0.02 0 0"/>
       <mass value="1.095"/>
       <inertia ixx="0.002" ixy="0" ixz="0" iyy="0.002" iyz="0" izz="0.001"/>
    </inertial>

    <visual>
      <origin rpy="0 0 0" xyz="0 0 0"/>
      <geometry>
        <mesh filename="ghost/hip.obj" scale="1 1 1"/>
      </geometry>
       <material name="blue"/>
    </visual>

     <collision>
      <origin rpy="0 0 0" xyz="0 0 0"/>
      <geometry>
        <mesh filename="ghost/hip.obj" scale="1 1 1"/>
      </geometry>
    </collision>
  </link>

  <joint name="RR_hip_joint" type="continuous">
    <axis xyz="1 0 0"/>
    <parent link="trunk"/>
    <child link="RR_hip"/>
    <origin rpy="1.57079 0 3.14159" xyz="-0.22 -0.06 0.0"/>
    <limit effort="100" velocity="100"/>
    <joint_properties damping=".0" friction=".0"/>
  </joint>

  <!-- RR UPPER LEG -->
  <link name="RR_upper">
  <!-- <contact>
      <lateral_friction value="1"/>
  </contact> -->
    <inertial>
     <origin rpy="0 0 0" xyz="0 -0.04 -0.04"/>
       <mass value="1.527"/>
       <inertia ixx="0.016" ixy="0" ixz="0" iyy="0.007" iyz="0" izz="0.011"/>
    </inertial>
       <visual>
      <origin rpy="0 0 0" xyz="0 0 0"/>
      <geometry>
        <mesh filename="ghost/upper_leg_mirror.obj" scale="1 1 1"/>
      </geometry>
       <material name="blue"/>
    </visual>

    <collision>
      <origin rpy="0 0 0" xyz="0 0 0"/>
      <geometry>
        <mesh filename="ghost/upper_leg_mirror.obj" scale="1 1 1"/>
      </geometry>
    </collision>
  </link>

  <joint name="RR_upper_joint" type="continuous">
    <axis xyz="0 1 0"/>
    <parent link="RR_hip"/>
    <child link="RR_upper"/>
    <origin rpy="1.57079 0 1.57079" xyz="-0.0015 0 -0.095"/>
    <limit effort="100" velocity="100"/>
    <joint_properties damping=".0" friction=".0"/>
  </joint>

  <!-- RR LOWER LEG -->
  <link name="RR_lower">
  <!-- <contact>
      <lateral_friction value="1"/>
  </contact> -->
    <inertial>
      <origin rpy="0 0 0" xyz="0 -0.16 -0.02"/>
       <mass value="0.241"/>
       <inertia ixx="0.002" ixy="0" ixz="0" iyy="0.002" iyz="0" izz="0.002"/>
    </inertial>
       <visual>
      <origin rpy="1.57079 1.57079 0" xyz="0 0 0"/>
      <geometry>
        <mesh filename="ghost/lower_leg.obj" scale="1 1 1"/>
      </geometry>
       <material name="grey"/>
    </visual>

     <collision>
      <origin rpy="1.57079 1.57079 0" xyz="0 0 0"/>
      <geometry>
        <mesh filename="ghost/lower_leg.obj" scale="1 1 1"/>
      </geometry>
    </collision>
  </link>

  <joint name="RR_lower_joint" type="continuous">
    <axis xyz="0 1 0"/>
    <parent link="RR_upper"/>
    <child link="RR_lower"/>
    <origin rpy="0 0 0" xyz="-0.25 -0.005 0.006"/>
    <limit effort="100" lower="-2.69653369433" upper="-0.916297857297" velocity="100"/>
    <joint_properties damping=".0" friction=".0"/>
  </joint>

  <!-- RR TOE -->
  <link name="RR_toe">
    <!-- <contact>
      <friction_anchor/>
      <stiffness value="30000.0"/>
      <damping value="1000.0"/>
      <spinning_friction value="0.1"/>
      <lateral_friction value="1.0"/>
    </contact> -->
    <visual>
      <origin rpy="0 0 0" xyz="0 0 0"/>
      <geometry>
        <sphere radius="0.0"/>
      </geometry>
      <material name="black"/>
    </visual>
    <collision>
      <origin rpy="0 0 0" xyz="0 0 0"/>
      <geometry>
        <sphere radius="0.03"/>
      </geometry>
    </collision>
    <inertial>
      <mass value="0.1"/>
      <inertia ixx="0.000025" ixy="0" ixz="0" iyy="0.000025" iyz="0" izz="0.000025"/>
    </inertial>
  </link>

  <joint name="RR_toe_fixed" type="fixed">
    <parent link="RR_lower"/>
    <child link="RR_toe"/>
    <origin xyz="-0.25 0 -0.02"/>
    <dynamics damping="0.0" friction="0.0"/>
  </joint>

  <!-- RL HIP -->
  <link name="RL_hip">
  <!-- <contact>
      <lateral_friction value="1"/>
  </contact> -->
    <inertial>
      <origin rpy="0 0 0" xyz="-.02 0 0"/>
       <mass value="1.095"/>
       <inertia ixx="0.002" ixy="0" ixz="0" iyy="0.002" iyz="0" izz="0.001"/>
    </inertial>
    <visual>
      <origin rpy="0 0 0" xyz="0 0 0"/>
      <geometry>
        <mesh filename="ghost/hip.obj" scale="1 1 1"/>
      </geometry>
       <material name="blue"/>
    </visual>

    <collision>
      <origin rpy="0 0 0" xyz="0 0 0"/>
      <geometry>
        <mesh filename="ghost/hip.obj" scale="1 1 1"/>
      </geometry>
    </collision>
   </link>

   <joint name="RL_hip_joint" type="continuous">
    <axis xyz="1 0 0"/>
    <parent link="trunk"/>
    <child link="RL_hip"/>
    <origin rpy="-1.57079 0 3.14159" xyz="-0.22 0.06 0.0"/>
    <limit effort="100" velocity="100"/>
    <joint_properties damping=".0" friction=".0"/>
  </joint>

  <!-- RL UPPER LEG -->
  <link name="RL_upper">
  <!-- <contact>
      <lateral_friction value="1"/>
  </contact> -->
    <inertial>
      <origin rpy="0 0 0" xyz="0 -0.04 -0.04"/>
       <mass value="1.527"/>
       <inertia ixx="0.016" ixy="0" ixz="0" iyy="0.007" iyz="0" izz="0.011"/>
    </inertial>
     <visual>
      <origin rpy="0 0 0" xyz="0 0 0"/>
      <geometry>
        <mesh filename="ghost/upper_leg.obj" scale="1 1 1"/>
      </geometry>
       <material name="blue"/>
    </visual>

    <collision>
      <origin rpy="0 0 0" xyz="0 0 0"/>
      <geometry>
        <mesh filename="ghost/upper_leg.obj" scale="1 1 1"/>
      </geometry>
    </collision>
  </link>

  <joint name="RL_upper_joint" type="continuous">
    <axis xyz="0 0 -1"/>
    <parent link="RL_hip"/>
    <child link="RL_upper"/>
    <origin rpy="0 0 3.14159" xyz="-0.0015 0 -0.101"/>
    <limit effort="100" velocity="100"/>
    <joint_properties damping=".0" friction=".0"/>
  </joint>

  <!-- RL LOWER LEG -->
  <link name="RL_lower">
  <!-- <contact>
      <lateral_friction value="1"/>
  </contact> -->
    <inertial>
      <origin rpy="0 0 0" xyz="0 -0.16 -0.02"/>
       <mass value="0.241"/>
       <inertia ixx="0.002" ixy="0" ixz="0" iyy="0.002" iyz="0" izz="0.002"/>
    </inertial>
   <visual>
      <origin rpy="0 0 0" xyz="0 0 0"/>
      <geometry>
        <mesh filename="ghost/lower_leg.obj" scale="1 1 1"/>
      </geometry>
       <material name="grey"/>
    </visual>

    <collision>
      <origin rpy="0 0 0" xyz="0 0 0"/>
      <geometry>
        <mesh filename="ghost/lower_leg.obj" scale="1 1 1"/>
      </geometry>
    </collision>
  </link>

  <joint name="RL_lower_joint" type="continuous">
    <axis xyz="0 0 -1"/>
    <parent link="RL_upper"/>
    <child link="RL_lower"/>
    <origin rpy="0 0 0" xyz="-0.005 -0.25 0.006"/>
    <limit effort="100" velocity="100"/>
    <joint_properties damping=".0" friction=".0"/>
  </joint>

  <!-- RL TOE -->
  <link name="RL_toe">
    <!-- <contact>
      <friction_anchor/>
      <stiffness value="30000.0"/>
      <damping value="1000.0"/>
      <spinning_friction value="0.1"/>
      <lateral_friction value="1.0"/>
    </contact> -->
    <visual>
      <origin rpy="0 0 0" xyz="0 0 0"/>
      <geometry>
        <sphere radius="0.0"/>
      </geometry>
      <material name="black"/>
    </visual>
    <collision>
      <origin rpy="0 0 0" xyz="0 0 0"/>
      <geometry>
        <sphere radius="0.03"/>
      </geometry>
    </collision>
    <inertial>
      <mass value="0.1"/>
      <inertia ixx="0.000025" ixy="0" ixz="0" iyy="0.000025" iyz="0" izz="0.000025"/>
    </inertial>
  </link>

  <joint name="RL_toe_fixed" type="fixed">
    <parent link="RL_lower"/>
    <child link="RL_toe"/>
    <origin xyz="0.02 -0.25 0"/>
    <dynamics damping="0.0" friction="0.0"/>
  </joint>
</robot>