<?xml version="1.0" encoding="utf-8"?>
<robot name="ghost">
  <material name="black">
    <color rgba="0.0 0.0 0.0 1.0"/>
  </material>
  <material name="cyan">
    <color rgba="0.0 1.0 1.0 1.0"/>
  </material>
  <material name="grey">
    <color rgba="0.6 0.6 0.6 1.0"/>
  </material>
  <material name="silver">
    <color rgba="0.7 0.7 0.7 1.0"/>
  </material>

  <link name="trunk">
    <visual>
      <origin rpy="0 0 -1.5708" xyz="0 0 0"/>
      <geometry>
        <mesh filename="ghost/body.obj" scale="1 1 1"/>
      </geometry>
      <material name="cyan"/>
    </visual>
    <!-- <collision>
      <origin rpy="0 0 0" xyz="0 0 0"/>
      <geometry>
        <box size="0.267 0.194 0.114"/>
      </geometry>
    </collision> -->
    <collision>
      <origin rpy="0 0 0" xyz="0 0 0"/>
      <geometry>
        <mesh filename="ghost/body.obj" scale="1 1 1"/>
      </geometry>
    </collision>
    <inertial>
      <origin rpy="0 0 0" xyz="0 0 0"/>
      <mass value="13.715"/>
      <inertia ixx="0.22" ixy="0" ixz="0" iyy="0.431" iyz="0" izz="0.565"/>
    </inertial>
  </link>

  <!-- FR HIP -->
  <link name="FR_hip">
    <!-- <contact>
      <lateral_friction value="1"/>
    </contact> -->
    <inertial>
      <origin rpy="0 0 0" xyz="0.02 0 0"/>
      <mass value="1.095"/>
      <inertia ixx="0.002" ixy="0" ixz="0" iyy=".002" iyz="0" izz=".001"/>
    </inertial>

    <visual>
      <origin rpy="0 0 0" xyz="0 0 0"/>
      <geometry>
        <mesh filename="ghost/hip.obj" scale="1 1 1"/>
      </geometry>
      <material name="grey"/>
    </visual>

    <collision>
      <origin rpy="0 0 0" xyz="0 0 0"/>
      <geometry>
        <mesh filename="ghost/hip.obj" scale="1 1 1"/>
      </geometry>
    </collision>
  </link>

  <joint name="FR_hip_joint" type="continuous">
    <axis xyz="1 0 0"/>
    <parent link="trunk"/>
    <child link="FR_hip"/>
    <origin rpy="1.57079 0 3.14159" xyz="0.22 -0.06 0.0"/>
    <limit effort="100" velocity="100"/>
    <joint_properties damping=".0" friction=".0"/>
  </joint>

  <!-- FR UPPER LEG -->
  <link name="FR_upper">
    <!-- <contact>
        <lateral_friction value="1"/>
    </contact> -->
    <inertial>
      <origin rpy="0 0 0" xyz="0 -0.04 -0.04"/>
      <mass value="1.527"/>
      <inertia ixx="0.015" ixy="0" ixz="0" iyy="0.007" iyz="0" izz="0.01"/>
    </inertial>
    <visual>
      <origin rpy="0 0 0" xyz="0 0 0"/>
      <geometry>
        <mesh filename="ghost/upper_leg_mirror.obj" scale="1 1 1"/>
      </geometry>
      <material name="black"/>
    </visual>

    <collision>
      <origin rpy="0 0 0" xyz="0 0 0"/>
      <geometry>
        <mesh filename="ghost/upper_leg_mirror.obj" scale="1 1 1"/>
      </geometry>
    </collision>
  </link>

  <joint name="FR_upper_joint" type="continuous">
    <axis xyz="0 1 0"/>
    <parent link="FR_hip"/>
    <child link="FR_upper"/>
    <origin rpy="1.57079 0 1.57079" xyz="-0.0015 0 -0.095"/>
    <limit effort="100" velocity="100"/>
    <joint_properties damping=".0" friction=".0"/>
  </joint>

  <!-- FR LOWER LEG -->
  <link name="FR_lower">
    <!-- <contact>
        <lateral_friction value="1"/>
    </contact> -->
    <inertial>
      <origin rpy="0 0 0" xyz="0 -0.16 -0.02"/>
      <mass value="0.241"/>
      <inertia ixx="0.002" ixy="0" ixz="0" iyy="0.002" iyz="0" izz="0.002"/>
    </inertial>
    <visual>
      <origin rpy="1.57079 1.57079 0" xyz="0 0.0 0"/>
      <geometry>
        <mesh filename="ghost/lower_leg.obj" scale="1 1 1"/>
      </geometry>
      <material name="grey"/>
    </visual>

    <collision>
      <origin rpy="1.57079 1.57079 0" xyz="0 0.0 0"/>
      <geometry>
        <mesh filename="ghost/lower_leg.obj" scale="1 1 1"/>
      </geometry>
    </collision>
  </link>

  <joint name="FR_lower_joint" type="continuous">
    <axis xyz="0 1 0"/>
    <parent link="FR_upper"/>
    <child link="FR_lower"/>
    <origin rpy="0 0 0" xyz="-0.25 -0.005 0.006"/>
    <limit effort="100" velocity="100"/>
    <joint_properties damping=".0" friction=".0"/>
  </joint>

  <!-- FR TOE -->
  <link name="FR_toe">
    <!-- <contact>
      <friction_anchor/>
      <stiffness value="30000.0"/>
      <damping value="1000.0"/>
      <spinning_friction value="0.1"/>
      <lateral_friction value="1.0"/>
    </contact> -->
    <visual>
      <origin rpy="0 0 0" xyz="0 0 0"/>
      <geometry>
        <sphere radius="0.0"/>
      </geometry>
      <material name="black"/>
    </visual>
    <collision>
      <origin rpy="0 0 0" xyz="0 0 0"/>
      <geometry>
        <sphere radius="0.03"/>
      </geometry>
    </collision>
    <inertial>
      <mass value="0.1"/>
      <inertia ixx="0.000025" ixy="0" ixz="0" iyy="0.000025" iyz="0" izz="0.000025"/>
    </inertial>
  </link>

  <joint name="FR_toe_fixed" type="fixed">
    <parent link="FR_lower"/>
    <child link="FR_toe"/>
    <origin xyz="-0.25 0 -0.02"/>
    <dynamics damping="0.0" friction="0.0"/>
  </joint>

  <!-- FL HIP -->
  <link name="FL_hip">
    <!-- <contact>
        <lateral_friction value="1"/>
    </contact> -->
    <inertial>
      <origin rpy="0 0 0" xyz="-.02 0 0"/>
      <mass value="1.095"/>
      <inertia ixx="0.002" ixy="0" ixz="0" iyy="0.002" iyz="0" izz="0.001"/>
    </inertial>
    <visual>
      <origin rpy="0 0 0" xyz="0 0 0"/>
      <geometry>
        <mesh filename="ghost/hip.obj" scale="1 1 1"/>
      </geometry>
      <material name="grey">
      </material>
    </visual>

    <collision>
      <origin rpy="0 0 0" xyz="0 0 0"/>
      <geometry>
        <mesh filename="ghost/hip.obj" scale="1 1 1"/>
      </geometry>
    </collision>
  </link>

  <joint name="FL_hip_joint" type="continuous">
    <axis xyz="1 0 0"/>
    <parent link="trunk"/>
    <child link="FL_hip"/>
    <origin rpy="-1.57079 0 3.14159" xyz="0.22 0.06 0.0"/>
    <limit effort="100" velocity="100"/>
    <joint_properties damping=".0" friction=".0"/>
  </joint>

  <!-- FL UPPER LEG -->
  <link name="FL_upper">
    <!-- <contact>
        <lateral_friction value="1"/>
    </contact> -->
    <inertial>
      <origin rpy="0 0 0" xyz="0 -0.04 -0.04"/>
      <mass value="1.527"/>
      <inertia ixx="0.016" ixy="0" ixz="0" iyy="0.007" iyz="0" izz="0.011"/>
    </inertial>
    <visual>
      <origin rpy="0 0 0" xyz="0 0 0"/>
      <geometry>

        <mesh filename="ghost/upper_leg.obj" scale="1 1 1"/>
      </geometry>
      <material name="black">
      </material>
    </visual>

    <collision>
      <origin rpy="0 0 0" xyz="0 0 0"/>
      <geometry>
        <mesh filename="ghost/upper_leg.obj" scale="1 1 1"/>
      </geometry>
    </collision>
  </link>


  <joint name="FL_upper_joint" type="continuous">
    <axis xyz="0 0 -1"/>
    <parent link="FL_hip"/>
    <child link="FL_upper"/>
    <origin rpy="0 0 3.14159" xyz="-0.0015 0 -0.101"/>
    <limit effort="100" velocity="100"/>
    <joint_properties damping=".0" friction=".0"/>
  </joint>

  <!-- FL LOWER LEG -->
  <link name="FL_lower">
    <!-- <contact>
        <lateral_friction value="1"/>
    </contact> -->
    <inertial>
      <origin rpy="0 0 0" xyz="0 -0.16 -0.02"/>
      <mass value="0.241"/>
      <inertia ixx="0.002" ixy="0" ixz="0" iyy="0.002" iyz="0" izz="0.002"/>
    </inertial>
    <visual>
      <origin rpy="0 0 0" xyz="0 0 0"/>
      <geometry>
        <mesh filename="ghost/lower_leg.obj" scale="1 1 1"/>
      </geometry>
      <material name="grey">
      </material>
    </visual>

    <collision>
      <origin rpy="0 0 0" xyz="0 0 0"/>
      <geometry>
        <mesh filename="ghost/lower_leg.obj" scale="1 1 1"/>
      </geometry>
    </collision>
  </link>

  <joint name="FL_lower_joint" type="continuous">
    <axis xyz="0 0 -1"/>
    <parent link="FL_upper"/>
    <child link="FL_lower"/>
    <origin rpy="0 0 0" xyz="-0.005 -0.25 0.006"/>
    <limit effort="100" velocity="100"/>
    <joint_properties damping=".0" friction=".0"/>
  </joint>

  <!-- FL TOE -->
  <link name="FL_toe">
    <!-- <contact>
      <friction_anchor/>
      <stiffness value="30000.0"/>
      <damping value="1000.0"/>
      <spinning_friction value="0.1"/>
      <lateral_friction value="1.0"/>
    </contact> -->
    <visual>
      <origin rpy="0 0 0" xyz="0 0 0"/>
      <geometry>
        <sphere radius="0.0"/>
      </geometry>
      <material name="black"/>
    </visual>
    <collision>
      <origin rpy="0 0 0" xyz="0 0 0"/>
      <geometry>
        <sphere radius="0.03"/>
      </geometry>
    </collision>
    <inertial>
      <mass value="0.1"/>
      <inertia ixx="0.000025" ixy="0" ixz="0" iyy="0.000025" iyz="0" izz="0.000025"/>
    </inertial>
  </link>

  <joint name="FL_toe_fixed" type="fixed">
    <parent link="FL_lower"/>
    <child link="FL_toe"/>
    <origin xyz="0.02 -0.25 0"/>
    <dynamics damping="0.0" friction="0.0"/>
  </joint>

  <!-- RR HIP -->
  <link name="RR_hip">
    <!-- <contact>
        <lateral_friction value="1"/>
    </contact> -->
    <inertial>
      <origin rpy="0 0 0" xyz="0.02 0 0"/>
      <mass value="1.095"/>
      <inertia ixx="0.002" ixy="0" ixz="0" iyy="0.002" iyz="0" izz="0.001"/>
    </inertial>

    <visual>
      <origin rpy="0 0 0" xyz="0 0 0"/>
      <geometry>
        <mesh filename="ghost/hip.obj" scale="1 1 1"/>
      </geometry>
      <material name="grey"/>
    </visual>

    <collision>
      <origin rpy="0 0 0" xyz="0 0 0"/>
      <geometry>
        <mesh filename="ghost/hip.obj" scale="1 1 1"/>
      </geometry>
    </collision>
  </link>

  <joint name="RR_hip_joint" type="continuous">
    <axis xyz="1 0 0"/>
    <parent link="trunk"/>
    <child link="RR_hip"/>
    <origin rpy="1.57079 0 3.14159" xyz="-0.22 -0.06 0.0"/>
    <limit effort="100" velocity="100"/>
    <joint_properties damping=".0" friction=".0"/>
  </joint>

  <!-- RR UPPER LEG -->
  <link name="RR_upper">
    <!-- <contact>
        <lateral_friction value="1"/>
    </contact> -->
    <inertial>
      <origin rpy="0 0 0" xyz="0 -0.04 -0.04"/>
      <mass value="1.527"/>
      <inertia ixx="0.016" ixy="0" ixz="0" iyy="0.007" iyz="0" izz="0.011"/>
    </inertial>
    <visual>
      <origin rpy="0 0 0" xyz="0 0 0"/>
      <geometry>
        <mesh filename="ghost/upper_leg_mirror.obj" scale="1 1 1"/>
      </geometry>
      <material name="black"/>
    </visual>

    <collision>
      <origin rpy="0 0 0" xyz="0 0 0"/>
      <geometry>
        <mesh filename="ghost/upper_leg_mirror.obj" scale="1 1 1"/>
      </geometry>
    </collision>
  </link>

  <joint name="RR_upper_joint" type="continuous">
    <axis xyz="0 1 0"/>
    <parent link="RR_hip"/>
    <child link="RR_upper"/>
    <origin rpy="1.57079 0 1.57079" xyz="-0.0015 0 -0.095"/>
    <limit effort="100" velocity="100"/>
    <joint_properties damping=".0" friction=".0"/>
  </joint>

  <!-- RR LOWER LEG -->
  <link name="RR_lower">
    <!-- <contact>
        <lateral_friction value="1"/>
    </contact> -->
    <inertial>
      <origin rpy="0 0 0" xyz="0 -0.16 -0.02"/>
      <mass value="0.241"/>
      <inertia ixx="0.002" ixy="0" ixz="0" iyy="0.002" iyz="0" izz="0.002"/>
    </inertial>
    <visual>
      <origin rpy="1.57079 1.57079 0" xyz="0 0 0"/>
      <geometry>
        <mesh filename="ghost/lower_leg.obj" scale="1 1 1"/>
      </geometry>
      <material name="grey"/>
    </visual>

    <collision>
      <origin rpy="1.57079 1.57079 0" xyz="0 0 0"/>
      <geometry>
        <mesh filename="ghost/lower_leg.obj" scale="1 1 1"/>
      </geometry>
    </collision>
  </link>

  <joint name="RR_lower_joint" type="continuous">
    <axis xyz="0 1 0"/>
    <parent link="RR_upper"/>
    <child link="RR_lower"/>
    <origin rpy="0 0 0" xyz="-0.25 -0.005 0.006"/>
    <limit effort="100" lower="-2.69653369433" upper="-0.916297857297" velocity="100"/>
    <joint_properties damping=".0" friction=".0"/>
  </joint>

  <!-- RR TOE -->
  <link name="RR_toe">
    <!-- <contact>
      <friction_anchor/>
      <stiffness value="30000.0"/>
      <damping value="1000.0"/>
      <spinning_friction value="0.1"/>
      <lateral_friction value="1.0"/>
    </contact> -->
    <visual>
      <origin rpy="0 0 0" xyz="0 0 0"/>
      <geometry>
        <sphere radius="0.0"/>
      </geometry>
      <material name="black"/>
    </visual>
    <collision>
      <origin rpy="0 0 0" xyz="0 0 0"/>
      <geometry>
        <sphere radius="0.03"/>
      </geometry>
    </collision>
    <inertial>
      <mass value="0.1"/>
      <inertia ixx="0.000025" ixy="0" ixz="0" iyy="0.000025" iyz="0" izz="0.000025"/>
    </inertial>
  </link>

  <joint name="RR_toe_fixed" type="fixed">
    <parent link="RR_lower"/>
    <child link="RR_toe"/>
    <origin xyz="-0.25 0 -0.02"/>
    <dynamics damping="0.0" friction="0.0"/>
  </joint>

  <!-- RL HIP -->
  <link name="RL_hip">
    <!-- <contact>
        <lateral_friction value="1"/>
    </contact> -->
    <inertial>
      <origin rpy="0 0 0" xyz="-.02 0 0"/>
      <mass value="1.095"/>
      <inertia ixx="0.002" ixy="0" ixz="0" iyy="0.002" iyz="0" izz="0.001"/>
    </inertial>
    <visual>
      <origin rpy="0 0 0" xyz="0 0 0"/>
      <geometry>
        <mesh filename="ghost/hip.obj" scale="1 1 1"/>
      </geometry>
      <material name="grey"/>
    </visual>

    <collision>
      <origin rpy="0 0 0" xyz="0 0 0"/>
      <geometry>
        <mesh filename="ghost/hip.obj" scale="1 1 1"/>
      </geometry>
    </collision>
  </link>

  <joint name="RL_hip_joint" type="continuous">
    <axis xyz="1 0 0"/>
    <parent link="trunk"/>
    <child link="RL_hip"/>
    <origin rpy="-1.57079 0 3.14159" xyz="-0.22 0.06 0.0"/>
    <limit effort="100" velocity="100"/>
    <joint_properties damping=".0" friction=".0"/>
  </joint>

  <!-- RL UPPER LEG -->
  <link name="RL_upper">
    <!-- <contact>
        <lateral_friction value="1"/>
    </contact> -->
    <inertial>
      <origin rpy="0 0 0" xyz="0 -0.04 -0.04"/>
      <mass value="1.527"/>
      <inertia ixx="0.016" ixy="0" ixz="0" iyy="0.007" iyz="0" izz="0.011"/>
    </inertial>
    <visual>
      <origin rpy="0 0 0" xyz="0 0 0"/>
      <geometry>
        <mesh filename="ghost/upper_leg.obj" scale="1 1 1"/>
      </geometry>
      <material name="black"/>
    </visual>

    <collision>
      <origin rpy="0 0 0" xyz="0 0 0"/>
      <geometry>
        <mesh filename="ghost/upper_leg.obj" scale="1 1 1"/>
      </geometry>
    </collision>
  </link>

  <joint name="RL_upper_joint" type="continuous">
    <axis xyz="0 0 -1"/>
    <parent link="RL_hip"/>
    <child link="RL_upper"/>
    <origin rpy="0 0 3.14159" xyz="-0.0015 0 -0.101"/>
    <limit effort="100" velocity="100"/>
    <joint_properties damping=".0" friction=".0"/>
  </joint>

  <!-- RL LOWER LEG -->
  <link name="RL_lower">
    <!-- <contact>
        <lateral_friction value="1"/>
    </contact> -->
    <inertial>
      <origin rpy="0 0 0" xyz="0 -0.16 -0.02"/>
      <mass value="0.241"/>
      <inertia ixx="0.002" ixy="0" ixz="0" iyy="0.002" iyz="0" izz="0.002"/>
    </inertial>
    <visual>
      <origin rpy="0 0 0" xyz="0 0 0"/>
      <geometry>
        <mesh filename="ghost/lower_leg.obj" scale="1 1 1"/>
      </geometry>
      <material name="grey"/>
    </visual>

    <collision>
      <origin rpy="0 0 0" xyz="0 0 0"/>
      <geometry>
        <mesh filename="ghost/lower_leg.obj" scale="1 1 1"/>
      </geometry>
    </collision>
  </link>

  <joint name="RL_lower_joint" type="continuous">
    <axis xyz="0 0 -1"/>
    <parent link="RL_upper"/>
    <child link="RL_lower"/>
    <origin rpy="0 0 0" xyz="-0.005 -0.25 0.006"/>
    <limit effort="100" velocity="100"/>
    <joint_properties damping=".0" friction=".0"/>
  </joint>

  <!-- RL TOE -->
  <link name="RL_toe">
    <!-- <contact>
      <friction_anchor/>
      <stiffness value="30000.0"/>
      <damping value="1000.0"/>
      <spinning_friction value="0.1"/>
      <lateral_friction value="1.0"/>
    </contact> -->
    <visual>
      <origin rpy="0 0 0" xyz="0 0 0"/>
      <geometry>
        <sphere radius="0.0"/>
      </geometry>
      <material name="black"/>
    </visual>
    <collision>
      <origin rpy="0 0 0" xyz="0 0 0"/>
      <geometry>
        <sphere radius="0.03"/>
      </geometry>
    </collision>
    <inertial>
      <mass value="0.1"/>
      <inertia ixx="0.000025" ixy="0" ixz="0" iyy="0.000025" iyz="0" izz="0.000025"/>
    </inertial>
  </link>

  <joint name="RL_toe_fixed" type="fixed">
    <parent link="RL_lower"/>
    <child link="RL_toe"/>
    <origin xyz="0.02 -0.25 0"/>
    <dynamics damping="0.0" friction="0.0"/>
  </joint>

  <!-- Arm -->
<!--  <link name="arm_base_link">-->
<!--    <inertial>-->
<!--      <origin rpy="0 0 0" xyz="0.009227173757711551 0.05711546040397183 -0.01795385944355127"/>-->
<!--      <mass value="0.5"/>-->
<!--      <inertia ixx="0.000507" ixy="1e-06" ixz="-6e-06" iyy="0.000506" iyz="2e-06" izz="0.000865"/>-->
<!--    </inertial>-->
<!--    <visual>-->
<!--      <origin rpy="0 0 0" xyz="0 0 0"/>-->
<!--      <geometry>-->
<!--        <mesh filename="spot_arm/base_link.stl" scale="0.001 0.001 0.001"/>-->
<!--      </geometry>-->
<!--      <material name="silver"/>-->
<!--    </visual>-->
<!--    <collision>-->
<!--      <origin rpy="0 0 0" xyz="0 0 0"/>-->
<!--      <geometry>-->
<!--        <mesh filename="spot_arm/base_link.stl" scale="0.001 0.001 0.001"/>-->
<!--      </geometry>-->
<!--    </collision>-->
<!--  </link>-->

<!--  <joint name="arm_base" type="fixed">-->
<!--    <origin rpy="0 0 0" xyz="0 -0.057 0.13"/>-->
<!--    <parent link="trunk"/>-->
<!--    <child link="arm_base_link"/>-->
<!--  </joint>-->

<!--  <link name="arm_link_1">-->
<!--    <inertial>-->
<!--      <origin rpy="0 0 0" xyz="4.3834423255225546e-05 1.851716180462093e-05 0.04608850485831119"/>-->
<!--      <mass value="0.5"/>-->
<!--      <inertia ixx="0.003419" ixy="1e-06" ixz="7e-06" iyy="0.015468" iyz="3e-06" izz="0.014948"/>-->
<!--    </inertial>-->
<!--    <visual>-->
<!--      <origin rpy="0 0 0" xyz="-0.009381 -0.055159 0.00311"/>-->
<!--      <geometry>-->
<!--        <mesh filename="spot_arm/bottom_v1_1.stl" scale="0.001 0.001 0.001"/>-->
<!--      </geometry>-->
<!--      <material name="silver"/>-->
<!--    </visual>-->
<!--    <collision>-->
<!--      <origin rpy="0 0 0" xyz="-0.009381 -0.055159 0.00311"/>-->
<!--      <geometry>-->
<!--        <mesh filename="spot_arm/bottom_v1_1.stl" scale="0.001 0.001 0.001"/>-->
<!--      </geometry>-->
<!--    </collision>-->
<!--  </link>-->

<!--  <joint name="motor_arm_0" type="continuous">-->
<!--    <origin rpy="0 0 0" xyz="0.009381 0.055159 -0.00311"/>-->
<!--    <parent link="arm_base_link"/>-->
<!--    <child link="arm_link_1"/>-->
<!--    <axis xyz="0.0 0.0 -1.0"/>-->
<!--  </joint>-->

<!--  <link name="arm_link_2">-->
<!--    <inertial>-->
<!--      <origin rpy="0 0 0" xyz="-0.03142910994215048 0.13773460820254285 -0.0002682558712496577"/>-->
<!--      <mass value="0.5"/>-->
<!--      <inertia ixx="0.031102" ixy="6.4e-05" ixz="-0.0" iyy="0.002102" iyz="8.3e-05" izz="0.031758"/>-->
<!--    </inertial>-->
<!--    <visual>-->
<!--      <origin rpy="0 0 0" xyz="-0.040881 -0.055159 -0.04679"/>-->
<!--      <geometry>-->
<!--        <mesh filename="spot_arm/Arm_1_v1_1.stl" scale="0.001 0.001 0.001"/>-->
<!--      </geometry>-->
<!--      <material name="silver"/>-->
<!--    </visual>-->
<!--    <collision>-->
<!--      <origin rpy="0 0 0" xyz="-0.040881 -0.055159 -0.04679"/>-->
<!--      <geometry>-->
<!--        <mesh filename="spot_arm/Arm_1_v1_1.stl" scale="0.001 0.001 0.001"/>-->
<!--      </geometry>-->
<!--    </collision>-->
<!--  </link>-->

<!--  <joint name="motor_arm_1" type="continuous">-->
<!--    <origin rpy="0 0 0" xyz="0.0315 0.0 0.0499"/>-->
<!--    <parent link="arm_link_1"/>-->
<!--    <child link="arm_link_2"/>-->
<!--    <axis xyz="1.0 -0.0 -0.0"/>-->
<!--  </joint>-->

<!--  <link name="arm_link_3">-->
<!--    <inertial>-->
<!--      <origin rpy="0 0 0" xyz="-0.0400132980912803 -0.11087815619558039 0.05350854885453979"/>-->
<!--      <mass value="0.5"/>-->
<!--      <inertia ixx="0.031386" ixy="-0.000713" ixz="7.5e-05" iyy="0.004183" iyz="0.004183" izz="0.032487"/>-->
<!--    </inertial>-->
<!--    <visual>-->
<!--      <origin rpy="0 0 0" xyz="-0.048281 -0.321159 -0.04679"/>-->
<!--      <geometry>-->
<!--        <mesh filename="spot_arm/Arm_2_v1_1.stl" scale="0.001 0.001 0.001"/>-->
<!--      </geometry>-->
<!--      <material name="silver"/>-->
<!--    </visual>-->
<!--    <collision>-->
<!--      <origin rpy="0 0 0" xyz="-0.048281 -0.321159 -0.04679"/>-->
<!--      <geometry>-->
<!--        <mesh filename="spot_arm/Arm_2_v1_1.stl" scale="0.001 0.001 0.001"/>-->
<!--      </geometry>-->
<!--    </collision>-->
<!--  </link>-->

<!--  <joint name="motor_arm_2" type="continuous">-->
<!--    <origin rpy="0 0 0" xyz="0.0074 0.266 0.0"/>-->
<!--    <parent link="arm_link_2"/>-->
<!--    <child link="arm_link_3"/>-->
<!--    <axis xyz="-1.0 0.0 -0.0"/>-->
<!--  </joint>-->

<!--  <link name="arm_link_4">-->
<!--    <inertial>-->
<!--      <origin rpy="0 0 0" xyz="0.02091414181608834 -0.018445992362037696 0.00022304823726640444"/>-->
<!--      <mass value="0.5"/>-->
<!--      <inertia ixx="0.000752" ixy="-3e-05" ixz="0.0" iyy="0.000408" iyz="4.8e-05" izz="0.000713"/>-->
<!--    </inertial>-->
<!--    <visual>-->
<!--      <origin rpy="0 0 0" xyz="0.009769 -0.021298 -0.120135"/>-->
<!--      <geometry>-->
<!--        <mesh filename="spot_arm/neck_v1_1.stl" scale="0.001 0.001 0.001"/>-->
<!--      </geometry>-->
<!--      <material name="silver"/>-->
<!--    </visual>-->
<!--    <collision>-->
<!--      <origin rpy="0 0 0" xyz="0.009769 -0.021298 -0.120135"/>-->
<!--      <geometry>-->
<!--        <mesh filename="spot_arm/neck_v1_1.stl" scale="0.001 0.001 0.001"/>-->
<!--      </geometry>-->
<!--    </collision>-->
<!--  </link>-->

<!--  <joint name="motor_arm_3" type="continuous">-->
<!--    <origin rpy="0 0 0" xyz="-0.05805 -0.299861 0.073345"/>-->
<!--    <parent link="arm_link_3"/>-->
<!--    <child link="arm_link_4"/>-->
<!--    <axis xyz="1.0 0.0 0.0"/>-->
<!--  </joint>-->

<!--  <link name="arm_link_5">-->
<!--    <inertial>-->
<!--      <origin rpy="0 0 0" xyz="0.0005326054691075326 -0.05481950519531094 -0.00779651999716835"/>-->
<!--      <mass value="0.5"/>-->
<!--      <inertia ixx="0.003243" ixy="3.8e-05" ixz="1.7e-05" iyy="0.001545" iyz="-0.000559" izz="0.002975"/>-->
<!--    </inertial>-->
<!--    <visual>-->
<!--      <origin rpy="0 0 0" xyz="-0.00937 0.027862 -0.124436"/>-->
<!--      <geometry>-->
<!--        <mesh filename="spot_arm/head_v1_1.stl" scale="0.001 0.001 0.001"/>-->
<!--      </geometry>-->
<!--      <material name="silver"/>-->
<!--    </visual>-->
<!--    <collision>-->
<!--      <origin rpy="0 0 0" xyz="-0.00937 0.027862 -0.124436"/>-->
<!--      <geometry>-->
<!--        <mesh filename="spot_arm/head_v1_1.stl" scale="0.001 0.001 0.001"/>-->
<!--      </geometry>-->
<!--    </collision>-->
<!--  </link>-->

<!--  <joint name="motor_arm_4" type="continuous">-->
<!--    <origin rpy="0 0 0" xyz="0.019139 -0.04916 0.004301"/>-->
<!--    <parent link="arm_link_4"/>-->
<!--    <child link="arm_link_5"/>-->
<!--    <axis xyz="-0.0 -0.996195 0.087156"/>-->
<!--  </joint>-->

<!--  <link name="arm_gripper">-->
<!--    <inertial>-->
<!--      <origin rpy="0 0 0" xyz="-0.032852931223272375 -0.04190244397153055 -0.015098287029036872"/>-->
<!--      <mass value="1"/>-->
<!--      <inertia ixx="0.000715" ixy="0.0" ixz="0.0" iyy="0.000727" iyz="-0.000254" izz="0.000856"/>-->
<!--    </inertial>-->
<!--    <visual>-->
<!--      <origin rpy="0 0 0" xyz="-0.044377 0.107781 -0.146383"/>-->
<!--      <geometry>-->
<!--        <mesh filename="spot_arm/gripper_v1_1.stl" scale="0.001 0.001 0.001"/>-->
<!--      </geometry>-->
<!--      <material name="silver"/>-->
<!--    </visual>-->
<!--    <collision>-->
<!--      <origin rpy="0 0 0" xyz="-0.044377 0.107781 -0.146383"/>-->
<!--      <geometry>-->
<!--        <mesh filename="spot_arm/gripper_v1_1.stl" scale="0.001 0.001 0.001"/>-->
<!--      </geometry>-->
<!--    </collision>-->
<!--  </link>-->

<!--  <joint name="motor_arm_5" type="continuous">-->
<!--    <origin rpy="0 0 0" xyz="0.035007 -0.079919 0.021947"/>-->
<!--    <parent link="arm_link_5"/>-->
<!--    <child link="arm_gripper"/>-->
<!--    <axis xyz="-1.0 0.0 -0.0"/>-->
<!--  </joint>-->

  <link name="arm_base_link">
    <inertial>
      <origin rpy="0 0 0" xyz="3.041253315481396e-05 3.5233638099900425e-06 0.034386377739529544"/>
      <mass value="0.28897197894505794"/>
      <inertia ixx="0.000561" ixy="-0.0" ixz="-0.0" iyy="0.000389" iyz="0.0" izz="0.000553"/>
    </inertial>
    <visual>
      <origin rpy="0 0 0" xyz="0 0 0"/>
      <geometry>
        <mesh filename="amber_b1/base_link.stl" scale="0.001 0.001 0.001"/>
      </geometry>
      <material name="silver"/>
    </visual>
    <collision>
      <origin rpy="0 0 0" xyz="0 0 0"/>
      <geometry>
        <mesh filename="amber_b1/base_link.stl" scale="0.001 0.001 0.001"/>
      </geometry>
    </collision>
  </link>

  <joint name="arm_base" type="fixed">
    <origin rpy="0 0 0" xyz="0 0 0"/>
    <parent link="trunk"/>
    <child link="arm_base_link"/>
  </joint>
  
  <link name="DOF1_1">
    <inertial>
      <origin rpy="0 0 0" xyz="-0.00015960906550393172 -1.2427845014393095e-05 -0.030235806886676903"/>
      <mass value="0.6510136315044379"/>
      <inertia ixx="0.000498" ixy="0.0" ixz="-3e-06" iyy="0.000484" iyz="-0.0" izz="0.000407"/>
    </inertial>
    <visual>
      <origin rpy="0 0 0" xyz="-0.0 -4e-06 -0.069966"/>
      <geometry>
        <mesh filename="amber_b1/DOF1_1.stl" scale="0.001 0.001 0.001"/>
      </geometry>
      <material name="silver"/>
    </visual>
    <collision>
      <origin rpy="0 0 0" xyz="-0.0 -4e-06 -0.069966"/>
      <geometry>
        <mesh filename="amber_b1/DOF1_1.stl" scale="0.001 0.001 0.001"/>
      </geometry>
    </collision>
  </link>
  
  <link name="DOF1_LINK_1">
    <inertial>
      <origin rpy="0 0 0" xyz="5.2085527568610045e-06 0.004977895400043735 0.07010343107502044"/>
      <mass value="0.935292940405524"/>
      <inertia ixx="0.001224" ixy="-0.0" ixz="-0.0" iyy="0.001136" iyz="-4.3e-05" izz="0.00072"/>
    </inertial>
    <visual>
      <origin rpy="0 0 0" xyz="-0.0 -4e-06 -0.074366"/>
      <geometry>
        <mesh filename="amber_b1/DOF1_LINK_1.stl" scale="0.001 0.001 0.001"/>
      </geometry>
      <material name="silver"/>
    </visual>
    <collision>
      <origin rpy="0 0 0" xyz="-0.0 -4e-06 -0.074366"/>
      <geometry>
        <mesh filename="amber_b1/DOF1_LINK_1.stl" scale="0.001 0.001 0.001"/>
      </geometry>
    </collision>
  </link>
  
  <link name="DOF2_1">
    <inertial>
      <origin rpy="0 0 0" xyz="-3.1921216491684105e-08 -0.011679501464314974 0.04696474149032967"/>
      <mass value="0.5984706718739643"/>
      <inertia ixx="0.001836" ixy="0.0" ixz="-0.0" iyy="0.001772" iyz="-0.000265" izz="0.000381"/>
    </inertial>
    <visual>
      <origin rpy="0 0 0" xyz="0.0 0.024996 -0.155566"/>
      <geometry>
        <mesh filename="amber_b1/DOF2_1.stl" scale="0.001 0.001 0.001"/>
      </geometry>
      <material name="silver"/>
    </visual>
    <collision>
      <origin rpy="0 0 0" xyz="0.0 0.024996 -0.155566"/>
      <geometry>
        <mesh filename="amber_b1/DOF2_1.stl" scale="0.001 0.001 0.001"/>
      </geometry>
    </collision>
  </link>
  
  <link name="DOF3_MOTOR_1">
    <inertial>
      <origin rpy="0 0 0" xyz="7.926931010823914e-05 3.749110346027253e-05 -0.0313458911509952"/>
      <mass value="0.5847003223149023"/>
      <inertia ixx="0.000404" ixy="0.0" ixz="2e-06" iyy="0.00039" iyz="1e-06" izz="0.000324"/>
    </inertial>
    <visual>
      <origin rpy="0 0 0" xyz="0.0 -0.000504 -0.278463"/>
      <geometry>
        <mesh filename="amber_b1/DOF3_MOTOR_1.stl" scale="0.001 0.001 0.001"/>
      </geometry>
      <material name="silver"/>
    </visual>
    <collision>
      <origin rpy="0 0 0" xyz="0.0 -0.000504 -0.278463"/>
      <geometry>
        <mesh filename="amber_b1/DOF3_MOTOR_1.stl" scale="0.001 0.001 0.001"/>
      </geometry>
    </collision>
  </link>
  
  <link name="DOF3_LINK_1">
    <inertial>
      <origin rpy="0 0 0" xyz="-5.21122742451035e-06 -0.004978087820401388 0.07040264166980847"/>
      <mass value="0.935292940405524"/>
      <inertia ixx="0.001224" ixy="-0.0" ixz="0.0" iyy="0.001136" iyz="4.3e-05" izz="0.00072"/>
    </inertial>
    <visual>
      <origin rpy="0 0 0" xyz="0.0 -0.000504 -0.283463"/>
      <geometry>
        <mesh filename="amber_b1/DOF3_LINK_1.stl" scale="0.001 0.001 0.001"/>
      </geometry>
      <material name="silver"/>
    </visual>
    <collision>
      <origin rpy="0 0 0" xyz="0.0 -0.000504 -0.283463"/>
      <geometry>
        <mesh filename="amber_b1/DOF3_LINK_1.stl" scale="0.001 0.001 0.001"/>
      </geometry>
    </collision>
  </link>
  
  <link name="DOF4_1">
    <inertial>
      <origin rpy="0 0 0" xyz="2.9261458020017447e-08 0.011679309041134928 0.04696395208618592"/>
      <mass value="0.5984706718739643"/>
      <inertia ixx="0.001836" ixy="0.0" ixz="0.0" iyy="0.001772" iyz="0.000265" izz="0.000381"/>
    </inertial>
    <visual>
      <origin rpy="0 0 0" xyz="0.0 -0.025504 -0.364963"/>
      <geometry>
        <mesh filename="amber_b1/DOF4_1.stl" scale="0.001 0.001 0.001"/>
      </geometry>
      <material name="silver"/>
    </visual>
    <collision>
      <origin rpy="0 0 0" xyz="0.0 -0.025504 -0.364963"/>
      <geometry>
        <mesh filename="amber_b1/DOF4_1.stl" scale="0.001 0.001 0.001"/>
      </geometry>
    </collision>
  </link>
  
  <link name="DOF5_MOTOR_1">
    <inertial>
      <origin rpy="0 0 0" xyz="-7.92719712862473e-05 -3.768352768190082e-05 -0.0313456805561112"/>
      <mass value="0.5847003223149023"/>
      <inertia ixx="0.000404" ixy="0.0" ixz="-2e-06" iyy="0.00039" iyz="-1e-06" izz="0.000324"/>
    </inertial>
    <visual>
      <origin rpy="0 0 0" xyz="-0.0 -4e-06 -0.487859"/>
      <geometry>
        <mesh filename="amber_b1/DOF5_MOTOR_1.stl" scale="0.001 0.001 0.001"/>
      </geometry>
      <material name="silver"/>
    </visual>
    <collision>
      <origin rpy="0 0 0" xyz="-0.0 -4e-06 -0.487859"/>
      <geometry>
        <mesh filename="amber_b1/DOF5_MOTOR_1.stl" scale="0.001 0.001 0.001"/>
      </geometry>
    </collision>
  </link>
  
  <link name="DOF5_link_1">
    <inertial>
      <origin rpy="0 0 0" xyz="5.208648522717918e-06 0.004977895391692929 0.07010285226492913"/>
      <mass value="0.935292940405524"/>
      <inertia ixx="0.001224" ixy="-0.0" ixz="-0.0" iyy="0.001136" iyz="-4.3e-05" izz="0.00072"/>
    </inertial>
    <visual>
      <origin rpy="0 0 0" xyz="-0.0 -4e-06 -0.492859"/>
      <geometry>
        <mesh filename="amber_b1/DOF5_link_1.stl" scale="0.001 0.001 0.001"/>
      </geometry>
      <material name="silver"/>
    </visual>
    <collision>
      <origin rpy="0 0 0" xyz="-0.0 -4e-06 -0.492859"/>
      <geometry>
        <mesh filename="amber_b1/DOF5_link_1.stl" scale="0.001 0.001 0.001"/>
      </geometry>
    </collision>
  </link>
  
  <link name="DOF6_LINK_1">
    <inertial>
      <origin rpy="0 0 0" xyz="-3.17560020832447e-08 -0.011679501474184246 0.04696416267915482"/>
      <mass value="0.5984706718739643"/>
      <inertia ixx="0.001836" ixy="0.0" ixz="-0.0" iyy="0.001772" iyz="-0.000265" izz="0.000381"/>
    </inertial>
    <visual>
      <origin rpy="0 0 0" xyz="-0.0 0.024996 -0.574059"/>
      <geometry>
        <mesh filename="amber_b1/DOF6_LINK_1.stl" scale="0.001 0.001 0.001"/>
      </geometry>
      <material name="silver"/>
    </visual>
    <collision>
      <origin rpy="0 0 0" xyz="-0.0 0.024996 -0.574059"/>
      <geometry>
        <mesh filename="amber_b1/DOF6_LINK_1.stl" scale="0.001 0.001 0.001"/>
      </geometry>
    </collision>
  </link>
  
  <link name="DOF7_MOTOR_1">
    <inertial>
      <origin rpy="0 0 0" xyz="7.926952865318467e-05 3.749109242478111e-05 -0.03134546996129095"/>
      <mass value="0.5847003223149023"/>
      <inertia ixx="0.000404" ixy="0.0" ixz="2e-06" iyy="0.00039" iyz="1e-06" izz="0.000324"/>
    </inertial>
    <visual>
      <origin rpy="0 0 0" xyz="0.0 -0.000504 -0.696955"/>
      <geometry>
        <mesh filename="amber_b1/DOF7_MOTOR_1.stl" scale="0.001 0.001 0.001"/>
      </geometry>
      <material name="silver"/>
    </visual>
    <collision>
      <origin rpy="0 0 0" xyz="0.0 -0.000504 -0.696955"/>
      <geometry>
        <mesh filename="amber_b1/DOF7_MOTOR_1.stl" scale="0.001 0.001 0.001"/>
      </geometry>
    </collision>
  </link>
  
  <link name="TOP_1">
    <inertial>
      <origin rpy="0 0 0" xyz="-4.963925281376204e-07 -0.00019582783329597517 0.01611980646593192"/>
      <mass value="0.15302388632599126"/>
      <inertia ixx="4.6e-05" ixy="0.0" ixz="0.0" iyy="5e-05" iyz="0.0" izz="5.5e-05"/>
    </inertial>
    <visual>
      <origin rpy="0 0 0" xyz="0.0 -0.000504 -0.701955"/>
      <geometry>
        <mesh filename="amber_b1/TOP_1.stl" scale="0.001 0.001 0.001"/>
      </geometry>
      <material name="silver"/>
    </visual>
    <collision>
      <origin rpy="0 0 0" xyz="0.0 -0.000504 -0.701955"/>
      <geometry>
        <mesh filename="amber_b1/TOP_1.stl" scale="0.001 0.001 0.001"/>
      </geometry>
    </collision>
  </link>
  
  <joint name="Rigid1" type="fixed">
    <origin rpy="0 0 0" xyz="0.0 4e-06 0.069966"/>
    <parent link="arm_base_link"/>
    <child link="DOF1_1"/>
  </joint>
  
  <joint name="motor_arm_0" type="continuous">
    <origin rpy="0 0 0" xyz="0.0 4e-06 0.074366"/>
    <parent link="arm_base_link"/>
    <child link="DOF1_LINK_1"/>
    <axis xyz="0.0 0.0 1.0"/>
  </joint>
  
  <joint name="motor_arm_1" type="continuous">
    <origin rpy="0 0 0" xyz="-0.0 -0.025 0.0812"/>
    <parent link="DOF1_LINK_1"/>
    <child link="DOF2_1"/>
    <axis xyz="0.0 1.0 -0.0"/>
  </joint>
  
  <joint name="Rigid5" type="fixed">
    <origin rpy="0 0 0" xyz="0.0 0.0255 0.122897"/>
    <parent link="DOF2_1"/>
    <child link="DOF3_MOTOR_1"/>
  </joint>
  
  <joint name="motor_arm_2" type="continuous">
    <origin rpy="0 0 0" xyz="0.0 0.0255 0.127897"/>
    <parent link="DOF2_1"/>
    <child link="DOF3_LINK_1"/>
    <axis xyz="0.0 -0.0 -1.0"/>
  </joint>
  
  <joint name="motor_arm_3" type="continuous">
    <origin rpy="0 0 0" xyz="0.0 0.025 0.0815"/>
    <parent link="DOF3_LINK_1"/>
    <child link="DOF4_1"/>
    <axis xyz="0.0 -1.0 -0.0"/>
  </joint>
  
  <joint name="Rigid8" type="fixed">
    <origin rpy="0 0 0" xyz="0.0 -0.0255 0.122896"/>
    <parent link="DOF4_1"/>
    <child link="DOF5_MOTOR_1"/>
  </joint>
  
  <joint name="motor_arm_4" type="continuous">
    <origin rpy="0 0 0" xyz="0.0 -0.0255 0.127896"/>
    <parent link="DOF4_1"/>
    <child link="DOF5_link_1"/>
    <axis xyz="-0.0 0.0 -1.0"/>
  </joint>
  
  <joint name="motor_arm_5" type="continuous">
    <origin rpy="0 0 0" xyz="0.0 -0.025 0.0812"/>
    <parent link="DOF5_link_1"/>
    <child link="DOF6_LINK_1"/>
    <axis xyz="0.0 1.0 0.0"/>
  </joint>
  
  <joint name="Rigid11" type="fixed">
    <origin rpy="0 0 0" xyz="-0.0 0.0255 0.122896"/>
    <parent link="DOF6_LINK_1"/>
    <child link="DOF7_MOTOR_1"/>
  </joint>
  
  <joint name="Rigid12" type="fixed">
    <origin rpy="0 0 0" xyz="-0.0 0.0255 0.127896"/>
    <parent link="DOF6_LINK_1"/>
    <child link="TOP_1"/>
  </joint>
</robot>