<?xml version="1.0" ?>
<!-- =================================================================================== -->
<!-- |    This document was autogenerated by xacro from /home/robot/catkin_ws/src/k3lso_robot_description/urdf/k3lso_robot.xacro | -->
<!-- |    EDITING THIS FILE BY HAND IS NOT RECOMMENDED                                 | -->
<!-- =================================================================================== -->
<robot name="k3lso_robot">
  <material name="silver_default">
    <color rgba="0.700 0.700 0.700 1.000"/>
  </material>
  <link name="base_link">
    <inertial>
      <origin rpy="0 0 0" xyz="3.934834505213609e-07 -1.3850611732515126e-07 0.001912983578096638"/>
      <mass value="4.385758280163802"/>
      <inertia ixx="0.020299" ixy="0.0" ixz="-0.0" iyy="0.102942" iyz="0.0" izz="0.116746"/>
    </inertial>
    <visual>
      <origin rpy="0 0 0" xyz="0 0 0"/>
      <geometry>
        <mesh filename="k3lso/base_link.stl" scale="0.001 0.001 0.001"/>
      </geometry>
      <material name="silver_default"/>
    </visual>
    <collision>
      <origin rpy="0 0 0" xyz="0 0 0"/>
      <geometry>
        <mesh filename="k3lso/obj/base_link.obj" scale="0.001 0.001 0.001"/>
      </geometry>
    </collision>
  </link>
  <link name="abduct_fr_1">
    <inertial>
      <origin rpy="0 0 0" xyz="0.05307764856594424 -0.0012595709556703638 0.00018956305199143559"/>
      <mass value="1.0694932881809627"/>
      <inertia ixx="0.000853" ixy="1.1e-05" ixz="1.3e-05" iyy="0.001356" iyz="-1e-06" izz="0.001003"/>
    </inertial>
    <visual>
      <origin rpy="0 0 0" xyz="-0.1845 0.055 0.000895"/>
      <geometry>
        <mesh filename="k3lso/abduct_fr_1.stl" scale="0.001 0.001 0.001"/>
      </geometry>
      <material name="silver_default"/>
    </visual>
    <collision>
      <origin rpy="0 0 0" xyz="-0.1845 0.055 0.000895"/>
      <geometry>
        <mesh filename="k3lso/obj/abduct_fr_1.obj" scale="0.001 0.001 0.001"/>
      </geometry>
    </collision>
  </link>
  <link name="thigh_hr_1">
    <inertial>
      <origin rpy="0 0 0" xyz="-0.0003218004337777469 -0.0596884157685139 -0.030289757148956896"/>
      <mass value="1.4760734131442261"/>
      <inertia ixx="0.008903" ixy="1.8e-05" ixz="-1.2e-05" iyy="0.008754" iyz="-0.001399" izz="0.001753"/>
    </inertial>
    <visual>
      <origin rpy="0 0 0" xyz="-0.24242 0.086937 0.001261"/>
      <geometry>
        <mesh filename="k3lso/obj/thigh_hr_1.obj" scale="0.001 0.001 0.001"/>
      </geometry>
      <material name="silver_default"/>
    </visual>
    <collision>
      <origin rpy="0 0 0" xyz="-0.24242 0.086937 0.001261"/>
      <geometry>
        <mesh filename="k3lso/obj/thigh_hr_1.obj" scale="0.001 0.001 0.001"/>
      </geometry>
    </collision>
  </link>
  <link name="shank_hl_1">
    <inertial>
      <origin rpy="0 0 0" xyz="0.014148114505737414 0.011199912515711286 -0.12186579885685311"/>
      <mass value="0.21899444921238967"/>
      <inertia ixx="0.0016" ixy="0.0" ixz="0.000106" iyy="0.001633" iyz="0.0" izz="4.8e-05"/>
    </inertial>
    <visual>
      <origin rpy="0 0 0" xyz="-0.242534 0.188457 0.281146"/>
      <geometry>
        <mesh filename="k3lso/obj/shank_hl_1.obj" scale="0.001 0.001 0.001"/>
      </geometry>
      <material name="silver_default"/>
    </visual>
    <collision>
      <origin rpy="0 0 0" xyz="-0.242534 0.188457 0.281146"/>
      <geometry>
        <mesh filename="k3lso/obj/shank_hl_1.obj" scale="0.001 0.001 0.001"/>
      </geometry>
    </collision>
  </link>
  <link name="toe_hr_1">
    <contact>
      <friction_anchor/>
      <stiffness value="30000.0"/>
      <damping value="1000.0"/>
      <spinning_friction value="0.1"/>
      <lateral_friction value="1.0"/>
    </contact>
    <inertial>
      <origin rpy="0 0 0" xyz="0.00458667149031633 -0.006500081766649929 0.010312470108147176"/>
      <mass value="0.03759501582149149"/>
      <inertia ixx="6e-06" ixy="0.0" ixz="1e-06" iyy="9e-06" iyz="0.0" izz="9e-06"/>
    </inertial>
    <visual>
      <origin rpy="0 0 0" xyz="-0.244786 0.170757 0.553397"/>
      <geometry>
        <mesh filename="k3lso/obj/toe_hr_1.obj" scale="0.001 0.001 0.001"/>
      </geometry>
      <material name="silver_default"/>
    </visual>
    <collision>
      <origin rpy="0 0 0" xyz="-0.244786 0.170757 0.553397"/>
      <geometry>
        <mesh filename="k3lso/obj/toe_hr_1.obj" scale="0.001 0.001 0.001"/>
      </geometry>
    </collision>
  </link>
  <link name="abduct_fl_1">
    <inertial>
      <origin rpy="0 0 0" xyz="0.05307764856594377 0.0012595709556728688 0.00018956305199150942"/>
      <mass value="1.0694932881809633"/>
      <inertia ixx="0.000853" ixy="-1.1e-05" ixz="1.3e-05" iyy="0.001356" iyz="1e-06" izz="0.001003"/>
    </inertial>
    <visual>
      <origin rpy="0 0 0" xyz="-0.1873 -0.055 0.000895"/>
      <geometry>
        <mesh filename="k3lso/obj/abduct_fl_1.obj" scale="0.001 0.001 0.001"/>
      </geometry>
      <material name="silver_default"/>
    </visual>
    <collision>
      <origin rpy="0 0 0" xyz="-0.1873 -0.055 0.000895"/>
      <geometry>
        <mesh filename="k3lso/obj/abduct_fl_1.obj" scale="0.001 0.001 0.001"/>
      </geometry>
    </collision>
  </link>
  <link name="thigh_hl_1">
    <inertial>
      <origin rpy="0 0 0" xyz="7.97981564236161e-05 0.05967684766881097 -0.029981675456800486"/>
      <mass value="1.4747243572805535"/>
      <inertia ixx="0.00885" ixy="3e-05" ixz="-3e-05" iyy="0.008752" iyz="0.001383" izz="0.001804"/>
    </inertial>
    <visual>
      <origin rpy="0 0 0" xyz="-0.24522 -0.086937 0.001261"/>
      <geometry>
        <mesh filename="k3lso/obj/thigh_hl_1.obj" scale="0.001 0.001 0.001"/>
      </geometry>
      <material name="silver_default"/>
    </visual>
    <collision>
      <origin rpy="0 0 0" xyz="-0.24522 -0.086937 0.001261"/>
      <geometry>
        <mesh filename="k3lso/obj/thigh_hl_1.obj" scale="0.001 0.001 0.001"/>
      </geometry>
    </collision>
  </link>
  <link name="shank_hl_2">
    <inertial>
      <origin rpy="0 0 0" xyz="0.014148091219917308 -0.011199912722097666 -0.12186580739310493"/>
      <mass value="0.21899444921238967"/>
      <inertia ixx="0.0016" ixy="0.0" ixz="0.000106" iyy="0.001633" iyz="0.0" izz="4.8e-05"/>
    </inertial>
    <visual>
      <origin rpy="0 0 0" xyz="-0.244306 -0.188457 0.280011"/>
      <geometry>
        <mesh filename="k3lso/obj/shank_hl_2.obj" scale="0.001 0.001 0.001"/>
      </geometry>
      <material name="silver_default"/>
    </visual>
    <collision>
      <origin rpy="0 0 0" xyz="-0.244306 -0.188457 0.280011"/>
      <geometry>
        <mesh filename="k3lso/obj/shank_hl_2.obj" scale="0.001 0.001 0.001"/>
      </geometry>
    </collision>
  </link>
  <link name="toe_hr_2">
    <contact>
      <friction_anchor/>
      <stiffness value="30000.0"/>
      <damping value="1000.0"/>
      <spinning_friction value="0.1"/>
      <lateral_friction value="1.0"/>
    </contact>
    <inertial>
      <origin rpy="0 0 0" xyz="0.004586648204496224 0.006500092995548129 0.01031246157189547"/>
      <mass value="0.03759501582149149"/>
      <inertia ixx="6e-06" ixy="0.0" ixz="1e-06" iyy="9e-06" iyz="0.0" izz="9e-06"/>
    </inertial>
    <visual>
      <origin rpy="0 0 0" xyz="-0.246558 -0.170757 0.552262"/>
      <geometry>
        <mesh filename="k3lso/obj/toe_hr_2.obj" scale="0.001 0.001 0.001"/>
      </geometry>
      <material name="silver_default"/>
    </visual>
    <collision>
      <origin rpy="0 0 0" xyz="-0.246558 -0.170757 0.552262"/>
      <geometry>
        <mesh filename="k3lso/obj/toe_hr_2.obj" scale="0.001 0.001 0.001"/>
      </geometry>
    </collision>
  </link>
  <link name="abduct_hr_1">
    <inertial>
      <origin rpy="0 0 0" xyz="-0.05307764856594402 -0.0012595709556719806 0.00018956305199565194"/>
      <mass value="1.0694932881809633"/>
      <inertia ixx="0.000853" ixy="-1.1e-05" ixz="-1.3e-05" iyy="0.001356" iyz="-1e-06" izz="0.001003"/>
    </inertial>
    <visual>
      <origin rpy="0 0 0" xyz="0.1873 0.055 0.000895"/>
      <geometry>
        <mesh filename="k3lso/obj/abduct_hr_1.obj" scale="0.001 0.001 0.001"/>
      </geometry>
      <material name="silver_default"/>
    </visual>
    <collision>
      <origin rpy="0 0 0" xyz="0.1873 0.055 0.000895"/>
      <geometry>
        <mesh filename="k3lso/obj/abduct_hr_1.obj" scale="0.001 0.001 0.001"/>
      </geometry>
    </collision>
  </link>
  <link name="thigh_hr_2">
    <inertial>
      <origin rpy="0 0 0" xyz="-0.0003216465512944078 -0.05968841576851537 -0.030289757148952635"/>
      <mass value="1.4760734131442261"/>
      <inertia ixx="0.008903" ixy="1.8e-05" ixz="-1.2e-05" iyy="0.008754" iyz="-0.001399" izz="0.001753"/>
    </inertial>
    <visual>
      <origin rpy="0 0 0" xyz="0.24522 0.086937 0.001261"/>
      <geometry>
        <mesh filename="k3lso/obj/thigh_hr_2.obj" scale="0.001 0.001 0.001"/>
      </geometry>
      <material name="silver_default"/>
    </visual>
    <collision>
      <origin rpy="0 0 0" xyz="0.24522 0.086937 0.001261"/>
      <geometry>
        <mesh filename="k3lso/obj/thigh_hr_2.obj" scale="0.001 0.001 0.001"/>
      </geometry>
    </collision>
  </link>
  <link name="shank_hl_3">
    <inertial>
      <origin rpy="0 0 0" xyz="0.014147268388201378 0.01119991251571023 -0.12186579885684973"/>
      <mass value="0.21899444921238967"/>
      <inertia ixx="0.0016" ixy="0.0" ixz="0.000106" iyy="0.001633" iyz="0.0" izz="4.8e-05"/>
    </inertial>
    <visual>
      <origin rpy="0 0 0" xyz="0.245105 0.188457 0.281146"/>
      <geometry>
        <mesh filename="k3lso/obj/shank_hl_3.obj" scale="0.001 0.001 0.001"/>
      </geometry>
      <material name="silver_default"/>
    </visual>
    <collision>
      <origin rpy="0 0 0" xyz="0.245105 0.188457 0.281146"/>
      <geometry>
        <mesh filename="k3lso/obj/shank_hl_3.obj" scale="0.001 0.001 0.001"/>
      </geometry>
    </collision>
  </link>
  <link name="toe_hr_3">
    <contact>
      <friction_anchor/>
      <stiffness value="30000.0"/>
      <damping value="1000.0"/>
      <spinning_friction value="0.1"/>
      <lateral_friction value="1.0"/>
    </contact>
    <inertial>
      <origin rpy="0 0 0" xyz="0.004586825372773412 -0.006500081766651011 0.010312470108151173"/>
      <mass value="0.03759501582149149"/>
      <inertia ixx="6e-06" ixy="0.0" ixz="1e-06" iyy="9e-06" iyz="0.0" izz="9e-06"/>
    </inertial>
    <visual>
      <origin rpy="0 0 0" xyz="0.242854 0.170757 0.553397"/>
      <geometry>
        <mesh filename="k3lso/obj/toe_hr_3.obj" scale="0.001 0.001 0.001"/>
      </geometry>
      <material name="silver_default"/>
    </visual>
    <collision>
      <origin rpy="0 0 0" xyz="0.242854 0.170757 0.553397"/>
      <geometry>
        <mesh filename="k3lso/obj/toe_hr_3.obj" scale="0.001 0.001 0.001"/>
      </geometry>
    </collision>
  </link>
  <link name="abduct_hl_1">
    <inertial>
      <origin rpy="0 0 0" xyz="-0.05307764856594449 0.0012595709556712173 0.00018956305199570355"/>
      <mass value="1.0694932881809625"/>
      <inertia ixx="0.000853" ixy="1.1e-05" ixz="-1.3e-05" iyy="0.001356" iyz="1e-06" izz="0.001003"/>
    </inertial>
    <visual>
      <origin rpy="0 0 0" xyz="0.1873 -0.055 0.000895"/>
      <geometry>
        <mesh filename="k3lso/obj/abduct_hl_1.obj" scale="0.001 0.001 0.001"/>
      </geometry>
      <material name="silver_default"/>
    </visual>
    <collision>
      <origin rpy="0 0 0" xyz="0.1873 -0.055 0.000895"/>
      <geometry>
        <mesh filename="k3lso/obj/abduct_hl_1.obj" scale="0.001 0.001 0.001"/>
      </geometry>
    </collision>
  </link>
  <link name="thigh_hl_2">
    <inertial>
      <origin rpy="0 0 0" xyz="7.995203890673319e-05 0.05967684766880969 -0.029981675456796107"/>
      <mass value="1.4747243572805535"/>
      <inertia ixx="0.00885" ixy="3e-05" ixz="-3e-05" iyy="0.008752" iyz="0.001383" izz="0.001804"/>
    </inertial>
    <visual>
      <origin rpy="0 0 0" xyz="0.24522 -0.086937 0.001261"/>
      <geometry>
        <mesh filename="k3lso/obj/thigh_hl_2.obj" scale="0.001 0.001 0.001"/>
      </geometry>
      <material name="silver_default"/>
    </visual>
    <collision>
      <origin rpy="0 0 0" xyz="0.24522 -0.086937 0.001261"/>
      <geometry>
        <mesh filename="k3lso/obj/thigh_hl_2.obj" scale="0.001 0.001 0.001"/>
      </geometry>
    </collision>
  </link>
  <link name="shank_hl_4">
    <inertial>
      <origin rpy="0 0 0" xyz="0.014147245102381162 -0.011199912722098415 -0.12186580739310016"/>
      <mass value="0.21899444921238967"/>
      <inertia ixx="0.0016" ixy="0.0" ixz="0.000106" iyy="0.001633" iyz="0.0" izz="4.8e-05"/>
    </inertial>
    <visual>
      <origin rpy="0 0 0" xyz="0.246133 -0.188457 0.280011"/>
      <geometry>
        <mesh filename="k3lso/obj/shank_hl_4.obj" scale="0.001 0.001 0.001"/>
      </geometry>
      <material name="silver_default"/>
    </visual>
    <collision>
      <origin rpy="0 0 0" xyz="0.246133 -0.188457 0.280011"/>
      <geometry>
        <mesh filename="k3lso/obj/shank_hl_4.obj" scale="0.001 0.001 0.001"/>
      </geometry>
    </collision>
  </link>
  <link name="toe_hr_4">
    <contact>
      <friction_anchor/>
      <stiffness value="30000.0"/>
      <damping value="1000.0"/>
      <spinning_friction value="0.1"/>
      <lateral_friction value="1.0"/>
    </contact>
    <inertial>
      <origin rpy="0 0 0" xyz="0.00458680208695289 0.006500092995547518 0.010312461571901133"/>
      <mass value="0.03759501582149149"/>
      <inertia ixx="6e-06" ixy="0.0" ixz="1e-06" iyy="9e-06" iyz="0.0" izz="9e-06"/>
    </inertial>
    <visual>
      <origin rpy="0 0 0" xyz="0.243882 -0.170757 0.552262"/>
      <geometry>
        <mesh filename="k3lso/obj/toe_hr_4.obj" scale="0.001 0.001 0.001"/>
      </geometry>
      <material name="silver_default"/>
    </visual>
    <collision>
      <origin rpy="0 0 0" xyz="0.243882 -0.170757 0.552262"/>
      <geometry>
        <mesh filename="k3lso/obj/toe_hr_4.obj" scale="0.001 0.001 0.001"/>
      </geometry>
    </collision>
  </link>
  <joint name="torso_to_abduct_fr_j" type="continuous">
    <origin rpy="0 0 0" xyz="0.1845 -0.055 -0.000895"/>
    <parent link="base_link"/>
    <child link="abduct_fr_1"/>
    <axis xyz="1.0 0.0 -0.0"/>
    <limit effort="54" velocity="100"/>
    <joint_properties damping=".0" friction=".0"/>
  </joint>
  <joint name="abduct_fr_to_thigh_fr_j" type="continuous">
    <origin rpy="0 0 0" xyz="0.05792 -0.031937 -0.000366"/>
    <parent link="abduct_fr_1"/>
    <child link="thigh_hr_1"/>
    <axis xyz="-0.0 1.0 -0.0"/>
    <limit effort="54" velocity="100"/>
    <joint_properties damping=".0" friction=".0"/>
  </joint>
  <joint name="thigh_fr_to_knee_fr_j" type="continuous">
    <origin rpy="0 0 0" xyz="0.000114 -0.10152 -0.279885"/>
    <parent link="thigh_hr_1"/>
    <child link="shank_hl_1"/>
    <axis xyz="-0.0 1.0 0.0"/>
    <limit effort="54" velocity="100"/>
    <joint_properties damping=".0" friction=".0"/>
  </joint>
  <joint name="fr_joint_toe" type="fixed">
    <origin rpy="0 0 0" xyz="0.002252 0.0177 -0.272251"/>
    <parent link="shank_hl_1"/>
    <child link="toe_hr_1"/>
    <dynamics damping="0.0" friction="0.0"/>
  </joint>
  <joint name="torso_to_abduct_fl_j" type="continuous">
    <origin rpy="0 0 0" xyz="0.1873 0.055 -0.000895"/>
    <parent link="base_link"/>
    <child link="abduct_fl_1"/>
    <axis xyz="-1.0 -0.0 0.0"/>
    <limit effort="54" velocity="100"/>
    <joint_properties damping=".0" friction=".0"/>
  </joint>
  <joint name="abduct_fl_to_thigh_fl_j" type="continuous">
    <origin rpy="0 0 0" xyz="0.05792 0.031937 -0.000366"/>
    <parent link="abduct_fl_1"/>
    <child link="thigh_hl_1"/>
    <axis xyz="0.0 1.0 0.0"/>
    <limit effort="54" velocity="100"/>
    <joint_properties damping=".0" friction=".0"/>
  </joint>
  <joint name="thigh_fl_to_knee_fl_j" type="continuous">
    <origin rpy="0 0 0" xyz="-0.000914 0.10152 -0.27875"/>
    <parent link="thigh_hl_1"/>
    <child link="shank_hl_2"/>
    <axis xyz="-0.0 -1.0 -0.0"/>
    <limit effort="54" velocity="100"/>
    <joint_properties damping=".0" friction=".0"/>
  </joint>
  <joint name="fl_joint_toe" type="fixed">
    <origin rpy="0 0 0" xyz="0.002252 -0.0177 -0.272251"/>
    <parent link="shank_hl_2"/>
    <child link="toe_hr_2"/>
    <dynamics damping="0.0" friction="0.0"/>
  </joint>
  <joint name="torso_to_abduct_hr_j" type="continuous">
    <origin rpy="0 0 0" xyz="-0.1873 -0.055 -0.000895"/>
    <parent link="base_link"/>
    <child link="abduct_hr_1"/>
    <axis xyz="1.0 0.0 -0.0"/>
    <limit effort="54" velocity="100"/>
    <joint_properties damping=".0" friction=".0"/>
  </joint>
  <joint name="abduct_hr_to_thigh_hr_j" type="continuous">
    <origin rpy="0 0 0" xyz="-0.05792 -0.031937 -0.000366"/>
    <parent link="abduct_hr_1"/>
    <child link="thigh_hr_2"/>
    <axis xyz="-0.0 -1.0 0.0"/>
    <limit effort="54" velocity="100"/>
    <joint_properties damping=".0" friction=".0"/>
  </joint>
  <joint name="thigh_hr_to_knee_hr_j" type="continuous">
    <origin rpy="0 0 0" xyz="0.000115 -0.10152 -0.279885"/>
    <parent link="thigh_hr_2"/>
    <child link="shank_hl_3"/>
    <axis xyz="-0.0 1.0 0.0"/>
    <limit effort="54" velocity="100"/>
    <joint_properties damping=".0" friction=".0"/>
  </joint>
  <joint name="hr_joint_toe" type="fixed">
    <origin rpy="0 0 0" xyz="0.002251 0.0177 -0.272251"/>
    <parent link="shank_hl_3"/>
    <child link="toe_hr_3"/>
    <dynamics damping="0.0" friction="0.0"/>
  </joint>
  <joint name="torso_to_abduct_hl_j" type="continuous">
    <origin rpy="0 0 0" xyz="-0.1873 0.055 -0.000895"/>
    <parent link="base_link"/>
    <child link="abduct_hl_1"/>
    <axis xyz="-1.0 -0.0 0.0"/>
    <limit effort="54" velocity="100"/>
    <joint_properties damping=".0" friction=".0"/>
  </joint>
  <joint name="abduct_hl_to_thigh_hl_j" type="continuous">
    <origin rpy="0 0 0" xyz="-0.05792 0.031937 -0.000366"/>
    <parent link="abduct_hl_1"/>
    <child link="thigh_hl_2"/>
    <axis xyz="0.0 -1.0 -0.0"/>
    <limit effort="54" velocity="100"/>
    <joint_properties damping=".0" friction=".0"/>
  </joint>
  <joint name="thigh_hl_to_knee_hl_j" type="continuous">
    <origin rpy="0 0 0" xyz="-0.000913 0.10152 -0.27875"/>
    <parent link="thigh_hl_2"/>
    <child link="shank_hl_4"/>
    <axis xyz="-0.0 -1.0 -0.0"/>
    <limit effort="54" velocity="100"/>
    <joint_properties damping=".0" friction=".0"/>
  </joint>
  <joint name="hl_joint_toe" type="fixed">
    <origin rpy="0 0 0" xyz="0.002251 -0.0177 -0.272251"/>
    <parent link="shank_hl_4"/>
    <child link="toe_hr_4"/>
    <dynamics damping="0.0" friction="0.0"/>
  </joint>
</robot>

