<?xml version="1.0" ?>
<!-- =================================================================================== -->
<!-- |    This document was autogenerated by xacro from /home/robot/catkin_ws/src/k3lso_robot_description/urdf/k3lso_robot.xacro | -->
<!-- |    EDITING THIS FILE BY HAND IS NOT RECOMMENDED                                 | -->
<!-- =================================================================================== -->
<robot name="k3lso_robot">
  <material name="silver_default">
    <color rgba="0.700 0.700 0.700 1.000"/>
  </material>
  <link name="base_link">
    <inertial>
      <origin rpy="0 0 0" xyz="3.934834505213609e-07 -1.3850611732515126e-07 0.001912983578096638"/>
      <mass value="4.385758280163802"/>
      <inertia ixx="0.020299" ixy="0.0" ixz="-0.0" iyy="0.102942" iyz="0.0" izz="0.116746"/>
    </inertial>
    <visual>
      <origin rpy="0 0 0" xyz="0 0 0"/>
      <geometry>
        <mesh filename="k3lso/base_link.stl" scale="0.001 0.001 0.001"/>
      </geometry>
      <material name="silver_default"/>
    </visual>
    <collision>
      <origin rpy="0 0 0" xyz="0 0 0"/>
      <geometry>
        <mesh filename="k3lso/obj/base_link.obj" scale="0.001 0.001 0.001"/>
      </geometry>
    </collision>
  </link>
  <link name="abduct_fr_1">
    <inertial>
      <origin rpy="0 0 0" xyz="0.05307764856594424 -0.0012595709556703638 0.00018956305199143559"/>
      <mass value="1.0694932881809627"/>
      <inertia ixx="0.000853" ixy="1.1e-05" ixz="1.3e-05" iyy="0.001356" iyz="-1e-06" izz="0.001003"/>
    </inertial>
    <visual>
      <origin rpy="0 0 0" xyz="-0.1845 0.055 0.000895"/>
      <geometry>
        <mesh filename="k3lso/abduct_fr_1.stl" scale="0.001 0.001 0.001"/>
      </geometry>
      <material name="silver_default"/>
    </visual>
    <collision>
      <origin rpy="0 0 0" xyz="-0.1845 0.055 0.000895"/>
      <geometry>
        <mesh filename="k3lso/obj/abduct_fr_1.obj" scale="0.001 0.001 0.001"/>
      </geometry>
    </collision>
  </link>
  <link name="thigh_hr_1">
    <inertial>
      <origin rpy="0 0 0" xyz="-0.0003218004337777469 -0.0596884157685139 -0.030289757148956896"/>
      <mass value="1.4760734131442261"/>
      <inertia ixx="0.008903" ixy="1.8e-05" ixz="-1.2e-05" iyy="0.008754" iyz="-0.001399" izz="0.001753"/>
    </inertial>
    <visual>
      <origin rpy="0 0 0" xyz="-0.24242 0.086937 0.001261"/>
      <geometry>
        <mesh filename="k3lso/obj/thigh_hr_1.obj" scale="0.001 0.001 0.001"/>
      </geometry>
      <material name="silver_default"/>
    </visual>
    <collision>
      <origin rpy="0 0 0" xyz="-0.24242 0.086937 0.001261"/>
      <geometry>
        <mesh filename="k3lso/obj/thigh_hr_1.obj" scale="0.001 0.001 0.001"/>
      </geometry>
    </collision>
  </link>
  <link name="shank_hl_1">
    <inertial>
      <origin rpy="0 0 0" xyz="0.014148114505737414 0.011199912515711286 -0.12186579885685311"/>
      <mass value="0.21899444921238967"/>
      <inertia ixx="0.0016" ixy="0.0" ixz="0.000106" iyy="0.001633" iyz="0.0" izz="4.8e-05"/>
    </inertial>
    <visual>
      <origin rpy="0 0 0" xyz="-0.242534 0.188457 0.281146"/>
      <geometry>
        <mesh filename="k3lso/obj/shank_hl_1.obj" scale="0.001 0.001 0.001"/>
      </geometry>
      <material name="silver_default"/>
    </visual>
    <collision>
      <origin rpy="0 0 0" xyz="-0.242534 0.188457 0.281146"/>
      <geometry>
        <mesh filename="k3lso/obj/shank_hl_1.obj" scale="0.001 0.001 0.001"/>
      </geometry>
    </collision>
  </link>
  <link name="toe_hr_1">
    <inertial>
      <origin rpy="0 0 0" xyz="0.00458667149031633 -0.006500081766649929 0.010312470108147176"/>
      <mass value="0.03759501582149149"/>
      <inertia ixx="6e-06" ixy="0.0" ixz="1e-06" iyy="9e-06" iyz="0.0" izz="9e-06"/>
    </inertial>
    <visual>
      <origin rpy="0 0 0" xyz="-0.244786 0.170757 0.553397"/>
      <geometry>
        <mesh filename="k3lso/obj/toe_hr_1.obj" scale="0.001 0.001 0.001"/>
      </geometry>
      <material name="silver_default"/>
    </visual>
    <collision>
      <origin rpy="0 0 0" xyz="-0.244786 0.170757 0.553397"/>
      <geometry>
        <mesh filename="k3lso/obj/toe_hr_1.obj" scale="0.001 0.001 0.001"/>
      </geometry>
    </collision>
  </link>
  <link name="abduct_fl_1">
    <inertial>
      <origin rpy="0 0 0" xyz="0.05307764856594377 0.0012595709556728688 0.00018956305199150942"/>
      <mass value="1.0694932881809633"/>
      <inertia ixx="0.000853" ixy="-1.1e-05" ixz="1.3e-05" iyy="0.001356" iyz="1e-06" izz="0.001003"/>
    </inertial>
    <visual>
      <origin rpy="0 0 0" xyz="-0.1873 -0.055 0.000895"/>
      <geometry>
        <mesh filename="k3lso/obj/abduct_fl_1.obj" scale="0.001 0.001 0.001"/>
      </geometry>
      <material name="silver_default"/>
    </visual>
    <collision>
      <origin rpy="0 0 0" xyz="-0.1873 -0.055 0.000895"/>
      <geometry>
        <mesh filename="k3lso/obj/abduct_fl_1.obj" scale="0.001 0.001 0.001"/>
      </geometry>
    </collision>
  </link>
  <link name="thigh_hl_1">
    <inertial>
      <origin rpy="0 0 0" xyz="7.97981564236161e-05 0.05967684766881097 -0.029981675456800486"/>
      <mass value="1.4747243572805535"/>
      <inertia ixx="0.00885" ixy="3e-05" ixz="-3e-05" iyy="0.008752" iyz="0.001383" izz="0.001804"/>
    </inertial>
    <visual>
      <origin rpy="0 0 0" xyz="-0.24522 -0.086937 0.001261"/>
      <geometry>
        <mesh filename="k3lso/obj/thigh_hl_1.obj" scale="0.001 0.001 0.001"/>
      </geometry>
      <material name="silver_default"/>
    </visual>
    <collision>
      <origin rpy="0 0 0" xyz="-0.24522 -0.086937 0.001261"/>
      <geometry>
        <mesh filename="k3lso/obj/thigh_hl_1.obj" scale="0.001 0.001 0.001"/>
      </geometry>
    </collision>
  </link>
  <link name="shank_hl_2">
    <inertial>
      <origin rpy="0 0 0" xyz="0.014148091219917308 -0.011199912722097666 -0.12186580739310493"/>
      <mass value="0.21899444921238967"/>
      <inertia ixx="0.0016" ixy="0.0" ixz="0.000106" iyy="0.001633" iyz="0.0" izz="4.8e-05"/>
    </inertial>
    <visual>
      <origin rpy="0 0 0" xyz="-0.244306 -0.188457 0.280011"/>
      <geometry>
        <mesh filename="k3lso/obj/shank_hl_2.obj" scale="0.001 0.001 0.001"/>
      </geometry>
      <material name="silver_default"/>
    </visual>
    <collision>
      <origin rpy="0 0 0" xyz="-0.244306 -0.188457 0.280011"/>
      <geometry>
        <mesh filename="k3lso/obj/shank_hl_2.obj" scale="0.001 0.001 0.001"/>
      </geometry>
    </collision>
  </link>
  <link name="toe_hr_2">
    <inertial>
      <origin rpy="0 0 0" xyz="0.004586648204496224 0.006500092995548129 0.01031246157189547"/>
      <mass value="0.03759501582149149"/>
      <inertia ixx="6e-06" ixy="0.0" ixz="1e-06" iyy="9e-06" iyz="0.0" izz="9e-06"/>
    </inertial>
    <visual>
      <origin rpy="0 0 0" xyz="-0.246558 -0.170757 0.552262"/>
      <geometry>
        <mesh filename="k3lso/obj/toe_hr_2.obj" scale="0.001 0.001 0.001"/>
      </geometry>
      <material name="silver_default"/>
    </visual>
    <collision>
      <origin rpy="0 0 0" xyz="-0.246558 -0.170757 0.552262"/>
      <geometry>
        <mesh filename="k3lso/obj/toe_hr_2.obj" scale="0.001 0.001 0.001"/>
      </geometry>
    </collision>
  </link>
  <link name="abduct_hr_1">
    <inertial>
      <origin rpy="0 0 0" xyz="-0.05307764856594402 -0.0012595709556719806 0.00018956305199565194"/>
      <mass value="1.0694932881809633"/>
      <inertia ixx="0.000853" ixy="-1.1e-05" ixz="-1.3e-05" iyy="0.001356" iyz="-1e-06" izz="0.001003"/>
    </inertial>
    <visual>
      <origin rpy="0 0 0" xyz="0.1873 0.055 0.000895"/>
      <geometry>
        <mesh filename="k3lso/obj/abduct_hr_1.obj" scale="0.001 0.001 0.001"/>
      </geometry>
      <material name="silver_default"/>
    </visual>
    <collision>
      <origin rpy="0 0 0" xyz="0.1873 0.055 0.000895"/>
      <geometry>
        <mesh filename="k3lso/obj/abduct_hr_1.obj" scale="0.001 0.001 0.001"/>
      </geometry>
    </collision>
  </link>
  <link name="thigh_hr_2">
    <inertial>
      <origin rpy="0 0 0" xyz="-0.0003216465512944078 -0.05968841576851537 -0.030289757148952635"/>
      <mass value="1.4760734131442261"/>
      <inertia ixx="0.008903" ixy="1.8e-05" ixz="-1.2e-05" iyy="0.008754" iyz="-0.001399" izz="0.001753"/>
    </inertial>
    <visual>
      <origin rpy="0 0 0" xyz="0.24522 0.086937 0.001261"/>
      <geometry>
        <mesh filename="k3lso/obj/thigh_hr_2.obj" scale="0.001 0.001 0.001"/>
      </geometry>
      <material name="silver_default"/>
    </visual>
    <collision>
      <origin rpy="0 0 0" xyz="0.24522 0.086937 0.001261"/>
      <geometry>
        <mesh filename="k3lso/obj/thigh_hr_2.obj" scale="0.001 0.001 0.001"/>
      </geometry>
    </collision>
  </link>
  <link name="shank_hl_3">
    <inertial>
      <origin rpy="0 0 0" xyz="0.014147268388201378 0.01119991251571023 -0.12186579885684973"/>
      <mass value="0.21899444921238967"/>
      <inertia ixx="0.0016" ixy="0.0" ixz="0.000106" iyy="0.001633" iyz="0.0" izz="4.8e-05"/>
    </inertial>
    <visual>
      <origin rpy="0 0 0" xyz="0.245105 0.188457 0.281146"/>
      <geometry>
        <mesh filename="k3lso/obj/shank_hl_3.obj" scale="0.001 0.001 0.001"/>
      </geometry>
      <material name="silver_default"/>
    </visual>
    <collision>
      <origin rpy="0 0 0" xyz="0.245105 0.188457 0.281146"/>
      <geometry>
        <mesh filename="k3lso/obj/shank_hl_3.obj" scale="0.001 0.001 0.001"/>
      </geometry>
    </collision>
  </link>
  <link name="toe_hr_3">
    <inertial>
      <origin rpy="0 0 0" xyz="0.004586825372773412 -0.006500081766651011 0.010312470108151173"/>
      <mass value="0.03759501582149149"/>
      <inertia ixx="6e-06" ixy="0.0" ixz="1e-06" iyy="9e-06" iyz="0.0" izz="9e-06"/>
    </inertial>
    <visual>
      <origin rpy="0 0 0" xyz="0.242854 0.170757 0.553397"/>
      <geometry>
        <mesh filename="k3lso/obj/toe_hr_3.obj" scale="0.001 0.001 0.001"/>
      </geometry>
      <material name="silver_default"/>
    </visual>
    <collision>
      <origin rpy="0 0 0" xyz="0.242854 0.170757 0.553397"/>
      <geometry>
        <mesh filename="k3lso/obj/toe_hr_3.obj" scale="0.001 0.001 0.001"/>
      </geometry>
    </collision>
  </link>
  <link name="abduct_hl_1">
    <inertial>
      <origin rpy="0 0 0" xyz="-0.05307764856594449 0.0012595709556712173 0.00018956305199570355"/>
      <mass value="1.0694932881809625"/>
      <inertia ixx="0.000853" ixy="1.1e-05" ixz="-1.3e-05" iyy="0.001356" iyz="1e-06" izz="0.001003"/>
    </inertial>
    <visual>
      <origin rpy="0 0 0" xyz="0.1873 -0.055 0.000895"/>
      <geometry>
        <mesh filename="k3lso/obj/abduct_hl_1.obj" scale="0.001 0.001 0.001"/>
      </geometry>
      <material name="silver_default"/>
    </visual>
    <collision>
      <origin rpy="0 0 0" xyz="0.1873 -0.055 0.000895"/>
      <geometry>
        <mesh filename="k3lso/obj/abduct_hl_1.obj" scale="0.001 0.001 0.001"/>
      </geometry>
    </collision>
  </link>
  <link name="thigh_hl_2">
    <inertial>
      <origin rpy="0 0 0" xyz="7.995203890673319e-05 0.05967684766880969 -0.029981675456796107"/>
      <mass value="1.4747243572805535"/>
      <inertia ixx="0.00885" ixy="3e-05" ixz="-3e-05" iyy="0.008752" iyz="0.001383" izz="0.001804"/>
    </inertial>
    <visual>
      <origin rpy="0 0 0" xyz="0.24522 -0.086937 0.001261"/>
      <geometry>
        <mesh filename="k3lso/obj/thigh_hl_2.obj" scale="0.001 0.001 0.001"/>
      </geometry>
      <material name="silver_default"/>
    </visual>
    <collision>
      <origin rpy="0 0 0" xyz="0.24522 -0.086937 0.001261"/>
      <geometry>
        <mesh filename="k3lso/obj/thigh_hl_2.obj" scale="0.001 0.001 0.001"/>
      </geometry>
    </collision>
  </link>
  <link name="shank_hl_4">
    <inertial>
      <origin rpy="0 0 0" xyz="0.014147245102381162 -0.011199912722098415 -0.12186580739310016"/>
      <mass value="0.21899444921238967"/>
      <inertia ixx="0.0016" ixy="0.0" ixz="0.000106" iyy="0.001633" iyz="0.0" izz="4.8e-05"/>
    </inertial>
    <visual>
      <origin rpy="0 0 0" xyz="0.246133 -0.188457 0.280011"/>
      <geometry>
        <mesh filename="k3lso/obj/shank_hl_4.obj" scale="0.001 0.001 0.001"/>
      </geometry>
      <material name="silver_default"/>
    </visual>
    <collision>
      <origin rpy="0 0 0" xyz="0.246133 -0.188457 0.280011"/>
      <geometry>
        <mesh filename="k3lso/obj/shank_hl_4.obj" scale="0.001 0.001 0.001"/>
      </geometry>
    </collision>
  </link>
  <link name="toe_hr_4">
    <inertial>
      <origin rpy="0 0 0" xyz="0.00458680208695289 0.006500092995547518 0.010312461571901133"/>
      <mass value="0.03759501582149149"/>
      <inertia ixx="6e-06" ixy="0.0" ixz="1e-06" iyy="9e-06" iyz="0.0" izz="9e-06"/>
    </inertial>
    <visual>
      <origin rpy="0 0 0" xyz="0.243882 -0.170757 0.552262"/>
      <geometry>
        <mesh filename="k3lso/obj/toe_hr_4.obj" scale="0.001 0.001 0.001"/>
      </geometry>
      <material name="silver_default"/>
    </visual>
    <collision>
      <origin rpy="0 0 0" xyz="0.243882 -0.170757 0.552262"/>
      <geometry>
        <mesh filename="k3lso/obj/toe_hr_4.obj" scale="0.001 0.001 0.001"/>
      </geometry>
    </collision>
  </link>
  <joint name="torso_to_abduct_fr_j" type="continuous">
    <origin rpy="0 0 0" xyz="0.1845 -0.055 -0.000895"/>
    <parent link="base_link"/>
    <child link="abduct_fr_1"/>
    <axis xyz="1.0 0.0 -0.0"/>
  </joint>
  <joint name="abduct_fr_to_thigh_fr_j" type="continuous">
    <origin rpy="0 0 0" xyz="0.05792 -0.031937 -0.000366"/>
    <parent link="abduct_fr_1"/>
    <child link="thigh_hr_1"/>
    <axis xyz="-0.0 1.0 -0.0"/>
  </joint>
  <joint name="thigh_fr_to_knee_fr_j" type="continuous">
    <origin rpy="0 0 0" xyz="0.000114 -0.10152 -0.279885"/>
    <parent link="thigh_hr_1"/>
    <child link="shank_hl_1"/>
    <axis xyz="-0.0 1.0 0.0"/>
  </joint>
  <joint name="fr_joint_toe" type="fixed">
    <origin rpy="0 0 0" xyz="0.002252 0.0177 -0.272251"/>
    <parent link="shank_hl_1"/>
    <child link="toe_hr_1"/>
  </joint>
  <joint name="torso_to_abduct_fl_j" type="continuous">
    <origin rpy="0 0 0" xyz="0.1873 0.055 -0.000895"/>
    <parent link="base_link"/>
    <child link="abduct_fl_1"/>
    <axis xyz="-1.0 -0.0 0.0"/>
  </joint>
  <joint name="abduct_fl_to_thigh_fl_j" type="continuous">
    <origin rpy="0 0 0" xyz="0.05792 0.031937 -0.000366"/>
    <parent link="abduct_fl_1"/>
    <child link="thigh_hl_1"/>
    <axis xyz="0.0 1.0 0.0"/>
  </joint>
  <joint name="thigh_fl_to_knee_fl_j" type="continuous">
    <origin rpy="0 0 0" xyz="-0.000914 0.10152 -0.27875"/>
    <parent link="thigh_hl_1"/>
    <child link="shank_hl_2"/>
    <axis xyz="-0.0 -1.0 -0.0"/>
  </joint>
  <joint name="fl_joint_toe" type="fixed">
    <origin rpy="0 0 0" xyz="0.002252 -0.0177 -0.272251"/>
    <parent link="shank_hl_2"/>
    <child link="toe_hr_2"/>
  </joint>
  <joint name="torso_to_abduct_hr_j" type="continuous">
    <origin rpy="0 0 0" xyz="-0.1873 -0.055 -0.000895"/>
    <parent link="base_link"/>
    <child link="abduct_hr_1"/>
    <axis xyz="1.0 0.0 -0.0"/>
  </joint>
  <joint name="abduct_hr_to_thigh_hr_j" type="continuous">
    <origin rpy="0 0 0" xyz="-0.05792 -0.031937 -0.000366"/>
    <parent link="abduct_hr_1"/>
    <child link="thigh_hr_2"/>
    <axis xyz="-0.0 -1.0 0.0"/>
  </joint>
  <joint name="thigh_hr_to_knee_hr_j" type="continuous">
    <origin rpy="0 0 0" xyz="0.000115 -0.10152 -0.279885"/>
    <parent link="thigh_hr_2"/>
    <child link="shank_hl_3"/>
    <axis xyz="-0.0 1.0 0.0"/>
  </joint>
  <joint name="hr_joint_toe" type="fixed">
    <origin rpy="0 0 0" xyz="0.002251 0.0177 -0.272251"/>
    <parent link="shank_hl_3"/>
    <child link="toe_hr_3"/>
  </joint>
  <joint name="torso_to_abduct_hl_j" type="continuous">
    <origin rpy="0 0 0" xyz="-0.1873 0.055 -0.000895"/>
    <parent link="base_link"/>
    <child link="abduct_hl_1"/>
    <axis xyz="-1.0 -0.0 0.0"/>
  </joint>
  <joint name="abduct_hl_to_thigh_hl_j" type="continuous">
    <origin rpy="0 0 0" xyz="-0.05792 0.031937 -0.000366"/>
    <parent link="abduct_hl_1"/>
    <child link="thigh_hl_2"/>
    <axis xyz="0.0 -1.0 -0.0"/>
  </joint>
  <joint name="thigh_hl_to_knee_hl_j" type="continuous">
    <origin rpy="0 0 0" xyz="-0.000913 0.10152 -0.27875"/>
    <parent link="thigh_hl_2"/>
    <child link="shank_hl_4"/>
    <axis xyz="-0.0 -1.0 -0.0"/>
  </joint>
  <joint name="hl_joint_toe" type="fixed">
    <origin rpy="0 0 0" xyz="0.002251 -0.0177 -0.272251"/>
    <parent link="shank_hl_4"/>
    <child link="toe_hr_4"/>
  </joint>

  <link name="arm_base_link">
    <inertial>
      <origin rpy="0 0 0" xyz="3.041253315481396e-05 3.5233638099900425e-06 0.034386377739529544"/>
      <mass value="0.28897197894505794"/>
      <inertia ixx="0.000561" ixy="-0.0" ixz="-0.0" iyy="0.000389" iyz="0.0" izz="0.000553"/>
    </inertial>
    <visual>
      <origin rpy="0 0 0" xyz="0 0 0"/>
      <geometry>
        <mesh filename="amber_b1/base_link.stl" scale="0.001 0.001 0.001"/>
      </geometry>
      <material name="silver"/>
    </visual>
    <collision>
      <origin rpy="0 0 0" xyz="0 0 0"/>
      <geometry>
        <mesh filename="amber_b1/base_link.stl" scale="0.001 0.001 0.001"/>
      </geometry>
    </collision>
  </link>

  <joint name="arm_base" type="fixed">
    <origin rpy="0 0 0" xyz="0 0 0"/>
    <parent link="base_link"/>
    <child link="arm_base_link"/>
  </joint>

  <link name="DOF1_1">
    <inertial>
      <origin rpy="0 0 0" xyz="-0.00015960906550393172 -1.2427845014393095e-05 -0.030235806886676903"/>
      <mass value="0.6510136315044379"/>
      <inertia ixx="0.000498" ixy="0.0" ixz="-3e-06" iyy="0.000484" iyz="-0.0" izz="0.000407"/>
    </inertial>
    <visual>
      <origin rpy="0 0 0" xyz="-0.0 -4e-06 -0.069966"/>
      <geometry>
        <mesh filename="amber_b1/DOF1_1.stl" scale="0.001 0.001 0.001"/>
      </geometry>
      <material name="silver"/>
    </visual>
    <collision>
      <origin rpy="0 0 0" xyz="-0.0 -4e-06 -0.069966"/>
      <geometry>
        <mesh filename="amber_b1/DOF1_1.stl" scale="0.001 0.001 0.001"/>
      </geometry>
    </collision>
  </link>

  <link name="DOF1_LINK_1">
    <inertial>
      <origin rpy="0 0 0" xyz="5.2085527568610045e-06 0.004977895400043735 0.07010343107502044"/>
      <mass value="0.935292940405524"/>
      <inertia ixx="0.001224" ixy="-0.0" ixz="-0.0" iyy="0.001136" iyz="-4.3e-05" izz="0.00072"/>
    </inertial>
    <visual>
      <origin rpy="0 0 0" xyz="-0.0 -4e-06 -0.074366"/>
      <geometry>
        <mesh filename="amber_b1/DOF1_LINK_1.stl" scale="0.001 0.001 0.001"/>
      </geometry>
      <material name="silver"/>
    </visual>
    <collision>
      <origin rpy="0 0 0" xyz="-0.0 -4e-06 -0.074366"/>
      <geometry>
        <mesh filename="amber_b1/DOF1_LINK_1.stl" scale="0.001 0.001 0.001"/>
      </geometry>
    </collision>
  </link>

  <link name="DOF2_1">
    <inertial>
      <origin rpy="0 0 0" xyz="-3.1921216491684105e-08 -0.011679501464314974 0.04696474149032967"/>
      <mass value="0.5984706718739643"/>
      <inertia ixx="0.001836" ixy="0.0" ixz="-0.0" iyy="0.001772" iyz="-0.000265" izz="0.000381"/>
    </inertial>
    <visual>
      <origin rpy="0 0 0" xyz="0.0 0.024996 -0.155566"/>
      <geometry>
        <mesh filename="amber_b1/DOF2_1.stl" scale="0.001 0.001 0.001"/>
      </geometry>
      <material name="silver"/>
    </visual>
    <collision>
      <origin rpy="0 0 0" xyz="0.0 0.024996 -0.155566"/>
      <geometry>
        <mesh filename="amber_b1/DOF2_1.stl" scale="0.001 0.001 0.001"/>
      </geometry>
    </collision>
  </link>

  <link name="DOF3_MOTOR_1">
    <inertial>
      <origin rpy="0 0 0" xyz="7.926931010823914e-05 3.749110346027253e-05 -0.0313458911509952"/>
      <mass value="0.5847003223149023"/>
      <inertia ixx="0.000404" ixy="0.0" ixz="2e-06" iyy="0.00039" iyz="1e-06" izz="0.000324"/>
    </inertial>
    <visual>
      <origin rpy="0 0 0" xyz="0.0 -0.000504 -0.278463"/>
      <geometry>
        <mesh filename="amber_b1/DOF3_MOTOR_1.stl" scale="0.001 0.001 0.001"/>
      </geometry>
      <material name="silver"/>
    </visual>
    <collision>
      <origin rpy="0 0 0" xyz="0.0 -0.000504 -0.278463"/>
      <geometry>
        <mesh filename="amber_b1/DOF3_MOTOR_1.stl" scale="0.001 0.001 0.001"/>
      </geometry>
    </collision>
  </link>

  <link name="DOF3_LINK_1">
    <inertial>
      <origin rpy="0 0 0" xyz="-5.21122742451035e-06 -0.004978087820401388 0.07040264166980847"/>
      <mass value="0.935292940405524"/>
      <inertia ixx="0.001224" ixy="-0.0" ixz="0.0" iyy="0.001136" iyz="4.3e-05" izz="0.00072"/>
    </inertial>
    <visual>
      <origin rpy="0 0 0" xyz="0.0 -0.000504 -0.283463"/>
      <geometry>
        <mesh filename="amber_b1/DOF3_LINK_1.stl" scale="0.001 0.001 0.001"/>
      </geometry>
      <material name="silver"/>
    </visual>
    <collision>
      <origin rpy="0 0 0" xyz="0.0 -0.000504 -0.283463"/>
      <geometry>
        <mesh filename="amber_b1/DOF3_LINK_1.stl" scale="0.001 0.001 0.001"/>
      </geometry>
    </collision>
  </link>

  <link name="DOF4_1">
    <inertial>
      <origin rpy="0 0 0" xyz="2.9261458020017447e-08 0.011679309041134928 0.04696395208618592"/>
      <mass value="0.5984706718739643"/>
      <inertia ixx="0.001836" ixy="0.0" ixz="0.0" iyy="0.001772" iyz="0.000265" izz="0.000381"/>
    </inertial>
    <visual>
      <origin rpy="0 0 0" xyz="0.0 -0.025504 -0.364963"/>
      <geometry>
        <mesh filename="amber_b1/DOF4_1.stl" scale="0.001 0.001 0.001"/>
      </geometry>
      <material name="silver"/>
    </visual>
    <collision>
      <origin rpy="0 0 0" xyz="0.0 -0.025504 -0.364963"/>
      <geometry>
        <mesh filename="amber_b1/DOF4_1.stl" scale="0.001 0.001 0.001"/>
      </geometry>
    </collision>
  </link>

  <link name="DOF5_MOTOR_1">
    <inertial>
      <origin rpy="0 0 0" xyz="-7.92719712862473e-05 -3.768352768190082e-05 -0.0313456805561112"/>
      <mass value="0.5847003223149023"/>
      <inertia ixx="0.000404" ixy="0.0" ixz="-2e-06" iyy="0.00039" iyz="-1e-06" izz="0.000324"/>
    </inertial>
    <visual>
      <origin rpy="0 0 0" xyz="-0.0 -4e-06 -0.487859"/>
      <geometry>
        <mesh filename="amber_b1/DOF5_MOTOR_1.stl" scale="0.001 0.001 0.001"/>
      </geometry>
      <material name="silver"/>
    </visual>
    <collision>
      <origin rpy="0 0 0" xyz="-0.0 -4e-06 -0.487859"/>
      <geometry>
        <mesh filename="amber_b1/DOF5_MOTOR_1.stl" scale="0.001 0.001 0.001"/>
      </geometry>
    </collision>
  </link>

  <link name="DOF5_link_1">
    <inertial>
      <origin rpy="0 0 0" xyz="5.208648522717918e-06 0.004977895391692929 0.07010285226492913"/>
      <mass value="0.935292940405524"/>
      <inertia ixx="0.001224" ixy="-0.0" ixz="-0.0" iyy="0.001136" iyz="-4.3e-05" izz="0.00072"/>
    </inertial>
    <visual>
      <origin rpy="0 0 0" xyz="-0.0 -4e-06 -0.492859"/>
      <geometry>
        <mesh filename="amber_b1/DOF5_link_1.stl" scale="0.001 0.001 0.001"/>
      </geometry>
      <material name="silver"/>
    </visual>
    <collision>
      <origin rpy="0 0 0" xyz="-0.0 -4e-06 -0.492859"/>
      <geometry>
        <mesh filename="amber_b1/DOF5_link_1.stl" scale="0.001 0.001 0.001"/>
      </geometry>
    </collision>
  </link>

  <link name="DOF6_LINK_1">
    <inertial>
      <origin rpy="0 0 0" xyz="-3.17560020832447e-08 -0.011679501474184246 0.04696416267915482"/>
      <mass value="0.5984706718739643"/>
      <inertia ixx="0.001836" ixy="0.0" ixz="-0.0" iyy="0.001772" iyz="-0.000265" izz="0.000381"/>
    </inertial>
    <visual>
      <origin rpy="0 0 0" xyz="-0.0 0.024996 -0.574059"/>
      <geometry>
        <mesh filename="amber_b1/DOF6_LINK_1.stl" scale="0.001 0.001 0.001"/>
      </geometry>
      <material name="silver"/>
    </visual>
    <collision>
      <origin rpy="0 0 0" xyz="-0.0 0.024996 -0.574059"/>
      <geometry>
        <mesh filename="amber_b1/DOF6_LINK_1.stl" scale="0.001 0.001 0.001"/>
      </geometry>
    </collision>
  </link>

  <link name="DOF7_MOTOR_1">
    <inertial>
      <origin rpy="0 0 0" xyz="7.926952865318467e-05 3.749109242478111e-05 -0.03134546996129095"/>
      <mass value="0.5847003223149023"/>
      <inertia ixx="0.000404" ixy="0.0" ixz="2e-06" iyy="0.00039" iyz="1e-06" izz="0.000324"/>
    </inertial>
    <visual>
      <origin rpy="0 0 0" xyz="0.0 -0.000504 -0.696955"/>
      <geometry>
        <mesh filename="amber_b1/DOF7_MOTOR_1.stl" scale="0.001 0.001 0.001"/>
      </geometry>
      <material name="silver"/>
    </visual>
    <collision>
      <origin rpy="0 0 0" xyz="0.0 -0.000504 -0.696955"/>
      <geometry>
        <mesh filename="amber_b1/DOF7_MOTOR_1.stl" scale="0.001 0.001 0.001"/>
      </geometry>
    </collision>
  </link>

  <link name="TOP_1">
    <inertial>
      <origin rpy="0 0 0" xyz="-4.963925281376204e-07 -0.00019582783329597517 0.01611980646593192"/>
      <mass value="0.15302388632599126"/>
      <inertia ixx="4.6e-05" ixy="0.0" ixz="0.0" iyy="5e-05" iyz="0.0" izz="5.5e-05"/>
    </inertial>
    <visual>
      <origin rpy="0 0 0" xyz="0.0 -0.000504 -0.701955"/>
      <geometry>
        <mesh filename="amber_b1/TOP_1.stl" scale="0.001 0.001 0.001"/>
      </geometry>
      <material name="silver"/>
    </visual>
    <collision>
      <origin rpy="0 0 0" xyz="0.0 -0.000504 -0.701955"/>
      <geometry>
        <mesh filename="amber_b1/TOP_1.stl" scale="0.001 0.001 0.001"/>
      </geometry>
    </collision>
  </link>

  <joint name="Rigid1" type="fixed">
    <origin rpy="0 0 0" xyz="0.0 4e-06 0.069966"/>
    <parent link="arm_base_link"/>
    <child link="DOF1_1"/>
  </joint>

  <joint name="motor_arm_0" type="continuous">
    <origin rpy="0 0 0" xyz="0.0 4e-06 0.074366"/>
    <parent link="arm_base_link"/>
    <child link="DOF1_LINK_1"/>
    <axis xyz="0.0 0.0 1.0"/>
  </joint>

  <joint name="motor_arm_1" type="continuous">
    <origin rpy="0 0 0" xyz="-0.0 -0.025 0.0812"/>
    <parent link="DOF1_LINK_1"/>
    <child link="DOF2_1"/>
    <axis xyz="0.0 1.0 -0.0"/>
  </joint>

  <joint name="Rigid5" type="fixed">
    <origin rpy="0 0 0" xyz="0.0 0.0255 0.122897"/>
    <parent link="DOF2_1"/>
    <child link="DOF3_MOTOR_1"/>
  </joint>

  <joint name="motor_arm_2" type="continuous">
    <origin rpy="0 0 0" xyz="0.0 0.0255 0.127897"/>
    <parent link="DOF2_1"/>
    <child link="DOF3_LINK_1"/>
    <axis xyz="0.0 -0.0 -1.0"/>
  </joint>

  <joint name="motor_arm_3" type="continuous">
    <origin rpy="0 0 0" xyz="0.0 0.025 0.0815"/>
    <parent link="DOF3_LINK_1"/>
    <child link="DOF4_1"/>
    <axis xyz="0.0 -1.0 -0.0"/>
  </joint>

  <joint name="Rigid8" type="fixed">
    <origin rpy="0 0 0" xyz="0.0 -0.0255 0.122896"/>
    <parent link="DOF4_1"/>
    <child link="DOF5_MOTOR_1"/>
  </joint>

  <joint name="motor_arm_4" type="continuous">
    <origin rpy="0 0 0" xyz="0.0 -0.0255 0.127896"/>
    <parent link="DOF4_1"/>
    <child link="DOF5_link_1"/>
    <axis xyz="-0.0 0.0 -1.0"/>
  </joint>

  <joint name="motor_arm_5" type="continuous">
    <origin rpy="0 0 0" xyz="0.0 -0.025 0.0812"/>
    <parent link="DOF5_link_1"/>
    <child link="DOF6_LINK_1"/>
    <axis xyz="0.0 1.0 0.0"/>
  </joint>

  <joint name="Rigid11" type="fixed">
    <origin rpy="0 0 0" xyz="-0.0 0.0255 0.122896"/>
    <parent link="DOF6_LINK_1"/>
    <child link="DOF7_MOTOR_1"/>
  </joint>

  <joint name="Rigid12" type="fixed">
    <origin rpy="0 0 0" xyz="-0.0 0.0255 0.127896"/>
    <parent link="DOF6_LINK_1"/>
    <child link="TOP_1"/>
  </joint>
</robot>

