<?xml version="1.0" encoding="utf-8"?>
<robot name="k3lso">
  <material name="silver_default">
    <color rgba="0.700 0.700 0.700 1.000"/>
  </material>
  <link name="base_link">
    <inertial>
      <origin rpy="0 0 0" xyz="3.934834505213609e-07 -1.3850611732515126e-07 0.001912983578096638"/>
      <mass value="4.564437321207513"/>
      <inertia ixx="0.021126" ixy="0.0" ixz="-0.0" iyy="0.107136" iyz="0.0" izz="0.121502"/>
    </inertial>
    <visual>
      <origin rpy="0 0 0" xyz="0 0 0"/>
      <geometry>
        <mesh filename="k3lso/obj/base_link.obj" scale="0.001 0.001 0.001"/>
      </geometry>
      <material name="silver_default"/>
    </visual>
    <collision>
      <origin rpy="0 0 0" xyz="0 0 0"/>
      <geometry>
        <mesh filename="k3lso/obj/base_link.obj" scale="0.001 0.001 0.001"/>
      </geometry>
    </collision>
  </link>
  <link name="FR_hip_1">
    <inertial>
      <origin rpy="0 0 0" xyz="0.05307764856594424 -0.0012560707724303469 0.0002115167395930228"/>
      <mass value="1.1130652369587057"/>
      <inertia ixx="0.000888" ixy="1.2e-05" ixz="1.4e-05" iyy="0.001411" iyz="-7e-06" izz="0.001045"/>
    </inertial>
    <visual>
      <origin rpy="0 0 0" xyz="-0.1873 0.055 0.000895"/>
      <geometry>
        <mesh filename="k3lso/obj/FR_hip_1.obj" scale="0.001 0.001 0.001"/>
      </geometry>
      <material name="silver_default"/>
    </visual>
    <collision>
      <origin rpy="0 0 0" xyz="-0.1873 0.055 0.000895"/>
      <geometry>
        <mesh filename="k3lso/obj/FR_hip_1.obj" scale="0.001 0.001 0.001"/>
      </geometry>
    </collision>
  </link>
  <link name="FR_upper_1">
    <inertial>
      <origin rpy="0 0 0" xyz="-7.996605282489799e-05 -0.060191534313835185 -0.02893617117630162"/>
      <mass value="1.5348057188614275"/>
      <inertia ixx="0.00921" ixy="3.2e-05" ixz="3e-05" iyy="0.009056" iyz="-0.001565" izz="0.00193"/>
    </inertial>
    <visual>
      <origin rpy="0 0 0" xyz="-0.24522 0.086938 0.000703"/>
      <geometry>
        <mesh filename="k3lso/obj/FR_upper_1.obj" scale="0.001 0.001 0.001"/>
      </geometry>
      <material name="silver_default"/>
    </visual>
    <collision>
      <origin rpy="0 0 0" xyz="-0.24522 0.086938 0.000703"/>
      <geometry>
        <mesh filename="k3lso/obj/FR_upper_1.obj" scale="0.001 0.001 0.001"/>
      </geometry>
    </collision>
  </link>
  <link name="FR_lower_v1_1">
    <inertial>
      <origin rpy="0 0 0" xyz="0.014147963750867631 0.009071432395381385 -0.12204311486791486"/>
      <mass value="0.22791655135860578"/>
      <inertia ixx="0.001666" ixy="2e-06" ixz="0.00011" iyy="0.001699" iyz="-2.9e-05" izz="5e-05"/>
    </inertial>
    <visual>
      <origin rpy="0 0 0" xyz="-0.246133 0.193308 0.277639"/>
      <geometry>
        <mesh filename="k3lso/obj/FR_lower_v1_1.obj" scale="0.001 0.001 0.001"/>
      </geometry>
      <material name="silver_default"/>
    </visual>
    <collision>
      <origin rpy="0 0 0" xyz="-0.246133 0.193308 0.277639"/>
      <geometry>
        <mesh filename="k3lso/obj/FR_lower_v1_1.obj" scale="0.001 0.001 0.001"/>
      </geometry>
    </collision>
  </link>
  <link name="FR_toe_1">
    <inertial>
      <origin rpy="0 0 0" xyz="-0.0027784727986050473 -0.002664165117943651 -0.009370453349137886"/>
      <mass value="0.03759501582149027"/>
      <inertia ixx="6e-06" ixy="0.0" ixz="1e-06" iyy="9e-06" iyz="-0.0" izz="9e-06"/>
    </inertial>
    <visual>
      <origin rpy="0 0 0" xyz="-0.25575 0.184017 0.530363"/>
      <geometry>
        <mesh filename="k3lso/obj/FR_toe_1.obj" scale="0.001 0.001 0.001"/>
      </geometry>
      <material name="silver_default"/>
    </visual>
    <collision>
      <origin rpy="0 0 0" xyz="-0.25575 0.184017 0.530363"/>
      <geometry>
        <mesh filename="k3lso/obj/FR_toe_1.obj" scale="0.001 0.001 0.001"/>
      </geometry>
    </collision>
  </link>
  <link name="RL_hip_v1_1">
    <inertial>
      <origin rpy="0 0 0" xyz="-0.05307764878551266 0.0012626875072289795 0.00016755172644186147"/>
      <mass value="1.1130652298904702"/>
      <inertia ixx="0.000888" ixy="1.2e-05" ixz="-1.4e-05" iyy="0.001411" iyz="-6e-06" izz="0.001044"/>
    </inertial>
    <visual>
      <origin rpy="0 0 0" xyz="0.1873 -0.055 0.000895"/>
      <geometry>
        <mesh filename="k3lso/obj/RL_hip_v1_1.obj" scale="0.001 0.001 0.001"/>
      </geometry>
      <material name="silver_default"/>
    </visual>
    <collision>
      <origin rpy="0 0 0" xyz="0.1873 -0.055 0.000895"/>
      <geometry>
        <mesh filename="k3lso/obj/RL_hip_v1_1.obj" scale="0.001 0.001 0.001"/>
      </geometry>
    </collision>
  </link>
  <link name="RR_hip_v1_1">
    <inertial>
      <origin rpy="0 0 0" xyz="-0.05307764764555481 -0.001259570743191947 0.00018956269163178917"/>
      <mass value="1.113065269318445"/>
      <inertia ixx="0.000888" ixy="-1.2e-05" ixz="-1.4e-05" iyy="0.001411" iyz="-1e-06" izz="0.001044"/>
    </inertial>
    <visual>
      <origin rpy="0 0 0" xyz="0.1873 0.055 0.000895"/>
      <geometry>
        <mesh filename="k3lso/obj/RR_hip_v1_1.obj" scale="0.001 0.001 0.001"/>
      </geometry>
      <material name="silver_default"/>
    </visual>
    <collision>
      <origin rpy="0 0 0" xyz="0.1873 0.055 0.000895"/>
      <geometry>
        <mesh filename="k3lso/obj/RR_hip_v1_1.obj" scale="0.001 0.001 0.001"/>
      </geometry>
    </collision>
  </link>
  <link name="FL_hip_v1_1">
    <inertial>
      <origin rpy="0 0 0" xyz="0.05307764764555484 0.0012595707522186222 0.00018956267481162303"/>
      <mass value="1.1130652693184448"/>
      <inertia ixx="0.000888" ixy="-1.2e-05" ixz="1.4e-05" iyy="0.001411" iyz="1e-06" izz="0.001044"/>
    </inertial>
    <visual>
      <origin rpy="0 0 0" xyz="-0.1873 -0.055 0.000895"/>
      <geometry>
        <mesh filename="k3lso/obj/FL_hip_v1_1.obj" scale="0.001 0.001 0.001"/>
      </geometry>
      <material name="silver_default"/>
    </visual>
    <collision>
      <origin rpy="0 0 0" xyz="-0.1873 -0.055 0.000895"/>
      <geometry>
        <mesh filename="k3lso/obj/FL_hip_v1_1.obj" scale="0.001 0.001 0.001"/>
      </geometry>
    </collision>
  </link>
  <link name="RR_upper_1">
    <inertial>
      <origin rpy="0 0 0" xyz="-7.981217036714949e-05 -0.05967684760142501 -0.02998167537769887"/>
      <mass value="1.4747243562013714"/>
      <inertia ixx="0.00885" ixy="3e-05" ixz="3e-05" iyy="0.008752" iyz="-0.001383" izz="0.001804"/>
    </inertial>
    <visual>
      <origin rpy="0 0 0" xyz="0.24522 0.086937 0.001261"/>
      <geometry>
        <mesh filename="k3lso/obj/RR_upper_1.obj" scale="0.001 0.001 0.001"/>
      </geometry>
      <material name="silver_default"/>
    </visual>
    <collision>
      <origin rpy="0 0 0" xyz="0.24522 0.086937 0.001261"/>
      <geometry>
        <mesh filename="k3lso/obj/RR_upper_1.obj" scale="0.001 0.001 0.001"/>
      </geometry>
    </collision>
  </link>
  <link name="RR_lower_1">
    <inertial>
      <origin rpy="0 0 0" xyz="0.014148117633287799 0.011199910541250607 -0.12186586676331829"/>
      <mass value="0.22791655135860578"/>
      <inertia ixx="0.001666" ixy="0.0" ixz="0.00011" iyy="0.0017" iyz="-0.0" izz="5e-05"/>
    </inertial>
    <visual>
      <origin rpy="0 0 0" xyz="0.244307 0.188457 0.280011"/>
      <geometry>
        <mesh filename="k3lso/obj/RR_lower_1.obj" scale="0.001 0.001 0.001"/>
      </geometry>
      <material name="silver_default"/>
    </visual>
    <collision>
      <origin rpy="0 0 0" xyz="0.244307 0.188457 0.280011"/>
      <geometry>
<<<<<<< Updated upstream
        <mesh filename="k3lso/obj/abduct_hr_1.obj/" scale="0.001 0.001 0.001"/>
=======
        <mesh filename="k3lso/obj/RR_lower_1.obj" scale="0.001 0.001 0.001"/>
>>>>>>> Stashed changes
      </geometry>
    </collision>
  </link>
  <link name="RR_toe_1">
    <inertial>
      <origin rpy="0 0 0" xyz="-0.0027783189161922905 -0.002500081766773299 -0.009415538856714867"/>
      <mass value="0.03759501582149027"/>
      <inertia ixx="6e-06" ixy="0.0" ixz="1e-06" iyy="9e-06" iyz="0.0" izz="9e-06"/>
    </inertial>
    <visual>
      <origin rpy="0 0 0" xyz="0.23469 0.174757 0.532534"/>
      <geometry>
        <mesh filename="k3lso/obj/RR_toe_1.obj" scale="0.001 0.001 0.001"/>
      </geometry>
      <material name="silver_default"/>
    </visual>
    <collision>
      <origin rpy="0 0 0" xyz="0.23469 0.174757 0.532534"/>
      <geometry>
        <mesh filename="k3lso/obj/RR_toe_1.obj" scale="0.001 0.001 0.001"/>
      </geometry>
    </collision>
  </link>
  <link name="FL_upper_1">
    <inertial>
      <origin rpy="0 0 0" xyz="7.981829632511261e-05 0.059676847601549385 -0.029981675376058475"/>
      <mass value="1.5348057188683095"/>
      <inertia ixx="0.00921" ixy="3.1e-05" ixz="-3.1e-05" iyy="0.009109" iyz="0.001439" izz="0.001877"/>
    </inertial>
    <visual>
      <origin rpy="0 0 0" xyz="-0.24522 -0.086937 0.001261"/>
      <geometry>
        <mesh filename="k3lso/obj/FL_upper_1.obj" scale="0.001 0.001 0.001"/>
      </geometry>
      <material name="silver_default"/>
    </visual>
    <collision>
      <origin rpy="0 0 0" xyz="-0.24522 -0.086937 0.001261"/>
      <geometry>
        <mesh filename="k3lso/obj/FL_upper_1.obj" scale="0.001 0.001 0.001"/>
      </geometry>
    </collision>
  </link>
  <link name="RL_upper_1">
    <inertial>
      <origin rpy="0 0 0" xyz="7.997217882313445e-05 0.05914425442372012 -0.031018935381902077"/>
      <mass value="1.5348057188683095"/>
      <inertia ixx="0.00921" ixy="3.1e-05" ixz="-3.1e-05" iyy="0.009157" iyz="0.001312" izz="0.001829"/>
    </inertial>
    <visual>
      <origin rpy="0 0 0" xyz="0.24522 -0.086926 0.001818"/>
      <geometry>
        <mesh filename="k3lso/obj/RL_upper_1.obj" scale="0.001 0.001 0.001"/>
      </geometry>
      <material name="silver_default"/>
    </visual>
    <collision>
      <origin rpy="0 0 0" xyz="0.24522 -0.086926 0.001818"/>
      <geometry>
        <mesh filename="k3lso/obj/RL_upper_1.obj" scale="0.001 0.001 0.001"/>
      </geometry>
    </collision>
  </link>
  <link name="RL_lower_1">
    <inertial>
      <origin rpy="0 0 0" xyz="0.014147425432821409 0.009070813703185687 -0.12204246616131731"/>
      <mass value="0.22791655136022496"/>
      <inertia ixx="0.001666" ixy="2e-06" ixz="0.00011" iyy="0.001699" iyz="-2.9e-05" izz="5e-05"/>
    </inertial>
    <visual>
      <origin rpy="0 0 0" xyz="0.246133 -0.161169 0.281907"/>
      <geometry>
        <mesh filename="k3lso/obj/RL_lower_1.obj" scale="0.001 0.001 0.001"/>
      </geometry>
      <material name="silver_default"/>
    </visual>
    <collision>
      <origin rpy="0 0 0" xyz="0.246133 -0.161169 0.281907"/>
      <geometry>
        <mesh filename="k3lso/obj/RL_lower_1.obj" scale="0.001 0.001 0.001"/>
      </geometry>
    </collision>
  </link>
  <link name="FL_lower_1">
    <inertial>
      <origin rpy="0 0 0" xyz="0.014147271550343288 -0.011199914696849472 -0.12186586694755563"/>
      <mass value="0.22791655136022496"/>
      <inertia ixx="0.001666" ixy="0.0" ixz="0.00011" iyy="0.0017" iyz="-0.0" izz="5e-05"/>
    </inertial>
    <visual>
      <origin rpy="0 0 0" xyz="-0.244307 -0.188457 0.280011"/>
      <geometry>
        <mesh filename="k3lso/obj/FL_lower_1.obj" scale="0.001 0.001 0.001"/>
      </geometry>
      <material name="silver_default"/>
    </visual>
    <collision>
      <origin rpy="0 0 0" xyz="-0.244307 -0.188457 0.280011"/>
      <geometry>
        <mesh filename="k3lso/obj/FL_lower_1.obj" scale="0.001 0.001 0.001"/>
      </geometry>
    </collision>
  </link>
  <link name="FL_toe_1">
    <inertial>
      <origin rpy="0 0 0" xyz="-0.0027781649990482604 -0.002499907004456653 -0.009415539040203758"/>
      <mass value="0.03759501582148716"/>
      <inertia ixx="6e-06" ixy="0.0" ixz="1e-06" iyy="9e-06" iyz="0.0" izz="9e-06"/>
    </inertial>
    <visual>
      <origin rpy="0 0 0" xyz="-0.253923 -0.179757 0.532534"/>
      <geometry>
        <mesh filename="k3lso/obj/FL_toe_1.obj" scale="0.001 0.001 0.001"/>
      </geometry>
      <material name="silver_default"/>
    </visual>
    <collision>
      <origin rpy="0 0 0" xyz="-0.253923 -0.179757 0.532534"/>
      <geometry>
        <mesh filename="k3lso/obj/FL_toe_1.obj" scale="0.001 0.001 0.001"/>
      </geometry>
    </collision>
  </link>
  <link name="RL_toe_1">
    <inertial>
      <origin rpy="0 0 0" xyz="-0.0027790111165796327 -0.002663783809708664 -0.009370804641798847"/>
      <mass value="0.03759501582148716"/>
      <inertia ixx="6e-06" ixy="0.0" ixz="1e-06" iyy="9e-06" iyz="-0.0" izz="9e-06"/>
    </inertial>
    <visual>
      <origin rpy="0 0 0" xyz="0.236516 -0.170459 0.53463"/>
      <geometry>
        <mesh filename="k3lso/obj/RL_toe_1.obj" scale="0.001 0.001 0.001"/>
      </geometry>
      <material name="silver_default"/>
    </visual>
    <collision>
      <origin rpy="0 0 0" xyz="0.236516 -0.170459 0.53463"/>
      <geometry>
        <mesh filename="k3lso/obj/RL_toe_1.obj" scale="0.001 0.001 0.001"/>
      </geometry>
    </collision>
  </link>
  <joint name="FR_hip_joint" type="continuous">
    <origin rpy="0 0 0" xyz="0.1873 -0.055 -0.000895"/>
    <parent link="base_link"/>
    <child link="FR_hip_1"/>
    <axis xyz="1.0 0.0 -0.0"/>
  </joint>
  <joint name="FR_upper_joint" type="continuous">
    <origin rpy="0 0 0" xyz="0.05792 -0.031938 0.000192"/>
    <parent link="FR_hip_1"/>
    <child link="FR_upper_1"/>
    <axis xyz="-0.0 0.999848 -0.017452"/>
  </joint>
  <joint name="FR_lower_joint" type="continuous">
    <origin rpy="0 0 0" xyz="0.000913 -0.10637 -0.276936"/>
    <parent link="FR_upper_1"/>
    <child link="FR_lower_v1_1"/>
    <axis xyz="0.0 0.999848 -0.017452"/>
  </joint>
<<<<<<< Updated upstream
  <joint name="toe_fr_joint" type="fixed">
    <origin rpy="0 0 0" xyz="0.002252 0.0177 -0.272251"/>
    <parent link="shank_hl_1"/>
    <child link="toe_hr_1"/>
=======
  <joint name="FR_toe_fixed" type="fixed">
    <origin rpy="0 0 0" xyz="0.009617 0.009291 -0.252724"/>
    <parent link="FR_lower_v1_1"/>
    <child link="FR_toe_1"/>
>>>>>>> Stashed changes
  </joint>
  <joint name="RL_hip_joint" type="continuous">
    <origin rpy="0 0 0" xyz="-0.1873 0.055 -0.000895"/>
    <parent link="base_link"/>
    <child link="RL_hip_v1_1"/>
    <axis xyz="-1.0 -0.0 0.0"/>
  </joint>
<<<<<<< Updated upstream
  <joint name="abduct_fl_to_thigh_fl_j" type="continuous">
    <origin rpy="0 0 0" xyz="0.05792 0.031937 -0.000366"/>
    <parent link="abduct_fl_1"/>
    <child link="thigh_hl_1"/>
    <axis xyz="0.0 1.0 0.0"/>
  </joint>
  <joint name="thigh_fl_to_knee_fl_j" type="continuous">
    <origin rpy="0 0 0" xyz="-0.000914 0.10152 -0.27875"/>
    <parent link="thigh_hl_1"/>
    <child link="shank_hl_2"/>
    <axis xyz="-0.0 -1.0 -0.0"/>
  </joint>
  <joint name="toe_fl_joint" type="fixed">
    <origin rpy="0 0 0" xyz="0.002252 -0.0177 -0.272251"/>
    <parent link="shank_hl_2"/>
    <child link="toe_hr_2"/>
  </joint>
  <joint name="torso_to_abduct_hr_j" type="continuous">
=======
  <joint name="RR_hip_joint" type="continuous">
>>>>>>> Stashed changes
    <origin rpy="0 0 0" xyz="-0.1873 -0.055 -0.000895"/>
    <parent link="base_link"/>
    <child link="RR_hip_v1_1"/>
    <axis xyz="1.0 0.0 -0.0"/>
  </joint>
  <joint name="FL_hip_joint" type="continuous">
    <origin rpy="0 0 0" xyz="0.1873 0.055 -0.000895"/>
    <parent link="base_link"/>
    <child link="FL_hip_v1_1"/>
    <axis xyz="-1.0 -0.0 0.0"/>
  </joint>
  <joint name="RR_upper_joint" type="continuous">
    <origin rpy="0 0 0" xyz="-0.05792 -0.031937 -0.000366"/>
    <parent link="RR_hip_v1_1"/>
    <child link="RR_upper_1"/>
    <axis xyz="-0.0 -1.0 -0.0"/>
  </joint>
  <joint name="RR_lower_joint" type="continuous">
    <origin rpy="0 0 0" xyz="0.000913 -0.10152 -0.27875"/>
    <parent link="RR_upper_1"/>
    <child link="RR_lower_1"/>
    <axis xyz="0.0 1.0 -0.0"/>
  </joint>
<<<<<<< Updated upstream
  <joint name="toe_hr_joint" type="fixed">
    <origin rpy="0 0 0" xyz="0.002251 0.0177 -0.272251"/>
    <parent link="shank_hl_3"/>
    <child link="toe_hr_3"/>
=======
  <joint name="RR_toe_fixed" type="fixed">
    <origin rpy="0 0 0" xyz="0.009617 0.0137 -0.252523"/>
    <parent link="RR_lower_1"/>
    <child link="RR_toe_1"/>
>>>>>>> Stashed changes
  </joint>
  <joint name="FL_upper_joint" type="continuous">
    <origin rpy="0 0 0" xyz="0.05792 0.031937 -0.000366"/>
    <parent link="FL_hip_v1_1"/>
    <child link="FL_upper_1"/>
    <axis xyz="0.0 1.0 -0.0"/>
  </joint>
  <joint name="RL_upper_joint" type="continuous">
    <origin rpy="0 0 0" xyz="-0.05792 0.031926 -0.000923"/>
    <parent link="RL_hip_v1_1"/>
    <child link="RL_upper_1"/>
    <axis xyz="-0.0 -0.999848 0.017452"/>
  </joint>
  <joint name="RL_lower_joint" type="continuous">
    <origin rpy="0 0 0" xyz="-0.000913 0.074243 -0.280089"/>
    <parent link="RL_upper_1"/>
    <child link="RL_lower_1"/>
    <axis xyz="0.0 0.999848 -0.017452"/>
  </joint>
  <joint name="FL_lower_joint" type="continuous">
    <origin rpy="0 0 0" xyz="-0.000913 0.10152 -0.27875"/>
    <parent link="FL_upper_1"/>
    <child link="FL_lower_1"/>
    <axis xyz="-0.0 -1.0 -0.0"/>
  </joint>
<<<<<<< Updated upstream
  <joint name="toe_hl_joint" type="fixed">
    <origin rpy="0 0 0" xyz="0.002251 -0.0177 -0.272251"/>
    <parent link="shank_hl_4"/>
    <child link="toe_hr_4"/>
=======
  <joint name="FL_toe_fixed" type="fixed">
    <origin rpy="0 0 0" xyz="0.009616 -0.0087 -0.252523"/>
    <parent link="FL_lower_1"/>
    <child link="FL_toe_1"/>
  </joint>
  <joint name="RL_toe_fixed" type="fixed">
    <origin rpy="0 0 0" xyz="0.009617 0.00929 -0.252723"/>
    <parent link="RL_lower_1"/>
    <child link="RL_toe_1"/>
>>>>>>> Stashed changes
  </joint>
</robot>
